Workbook

Sheet DATA
A1: Estudiante | B1: Región | C1: Nivel | D1: Grado | E1: Institución Educativa | F1: Ambito | G1: Sexo | H1: R Producción de textos | I1: Año | J1: ANALISIS | K1: PADD-R | L1: ID IE | M1: ID2 | AI1: Año | AJ1: #
A2: 1 | B2: 48. Piura | C2: Primaria | D2: 4 Primaria | E2: =IFERROR(__xludf.DUMMYFUNCTION("FILTER(Colegios!$B$2:$B2419,Colegios!$A$2:$A2419=L2)"),"14924 DANIEL ALCIDES CARRION") -> 14924 DANIEL ALCIDES CARRION | F2: Rural | G2: Masculino | H2: Inicio | I2: 2024 | J2: =IFERROR(__xludf.DUMMYFUNCTION("FILTER('CLASFICACIÓN'!$F$3:$F2419,'CLASFICACIÓN'!$G$3:$G2419=M2)"),"SOLO 2024") -> SOLO 2024 | K2: PADD 2023 Y 2024 | L2: 14924 DANIEL ALCIDES CARRION | M2: =E2&D2 -> 14924 DANIEL ALCIDES CARRION4 Primaria | N2: =(SUMA(H3:S3)/BDEXTRAER(claves!$A$2:$I$8,claves!$I$2,{claves!$B$2;D3}))*50 | AJ2: =COUNTA(A2:A2419) -> 2418
A3: 2 | B3: 48. Piura | C3: Primaria | D3: 4 Primaria | E3: =IFERROR(__xludf.DUMMYFUNCTION("FILTER(Colegios!$B$2:$B2419,Colegios!$A$2:$A2419=L3)"),"14924 DANIEL ALCIDES CARRION") -> 14924 DANIEL ALCIDES CARRION | F3: Rural | G3: Masculino | H3: Inicio | I3: 2024 | J3: =IFERROR(__xludf.DUMMYFUNCTION("FILTER('CLASFICACIÓN'!$F$3:$F2419,'CLASFICACIÓN'!$G$3:$G2419=M3)"),"SOLO 2024") -> SOLO 2024 | K3: PADD 2023 Y 2024 | L3: 14924 DANIEL ALCIDES CARRION | M3: =E3&D3 -> 14924 DANIEL ALCIDES CARRION4 Primaria
A4: 3 | B4: 48. Piura | C4: Primaria | D4: 4 Primaria | E4: =IFERROR(__xludf.DUMMYFUNCTION("FILTER(Colegios!$B$2:$B2419,Colegios!$A$2:$A2419=L4)"),"14924 DANIEL ALCIDES CARRION") -> 14924 DANIEL ALCIDES CARRION | F4: Rural | G4: Masculino | H4: Proceso | I4: 2024 | J4: =IFERROR(__xludf.DUMMYFUNCTION("FILTER('CLASFICACIÓN'!$F$3:$F2419,'CLASFICACIÓN'!$G$3:$G2419=M4)"),"SOLO 2024") -> SOLO 2024 | K4: PADD 2023 Y 2024 | L4: 14924 DANIEL ALCIDES CARRION | M4: =E4&D4 -> 14924 DANIEL ALCIDES CARRION4 Primaria
A5: 4 | B5: 48. Piura | C5: Primaria | D5: 4 Primaria | E5: =IFERROR(__xludf.DUMMYFUNCTION("FILTER(Colegios!$B$2:$B2419,Colegios!$A$2:$A2419=L5)"),"14924 DANIEL ALCIDES CARRION") -> 14924 DANIEL ALCIDES CARRION | F5: Rural | G5: Femenino | H5: Proceso | I5: 2024 | J5: =IFERROR(__xludf.DUMMYFUNCTION("FILTER('CLASFICACIÓN'!$F$3:$F2419,'CLASFICACIÓN'!$G$3:$G2419=M5)"),"SOLO 2024") -> SOLO 2024 | K5: PADD 2023 Y 2024 | L5: 14924 DANIEL ALCIDES CARRION | M5: =E5&D5 -> 14924 DANIEL ALCIDES CARRION4 Primaria
A6: 5 | B6: 48. Piura | C6: Primaria | D6: 4 Primaria | E6: =IFERROR(__xludf.DUMMYFUNCTION("FILTER(Colegios!$B$2:$B2419,Colegios!$A$2:$A2419=L6)"),"14924 DANIEL ALCIDES CARRION") -> 14924 DANIEL ALCIDES CARRION | F6: Rural | G6: Masculino | H6: Proceso | I6: 2024 | J6: =IFERROR(__xludf.DUMMYFUNCTION("FILTER('CLASFICACIÓN'!$F$3:$F2419,'CLASFICACIÓN'!$G$3:$G2419=M6)"),"SOLO 2024") -> SOLO 2024 | K6: PADD 2023 Y 2024 | L6: 14924 DANIEL ALCIDES CARRION | M6: =E6&D6 -> 14924 DANIEL ALCIDES CARRION4 Primaria
A7: 6 | B7: 48. Piura | C7: Primaria | D7: 4 Primaria | E7: =IFERROR(__xludf.DUMMYFUNCTION("FILTER(Colegios!$B$2:$B2419,Colegios!$A$2:$A2419=L7)"),"14924 DANIEL ALCIDES CARRION") -> 14924 DANIEL ALCIDES CARRION | F7: Rural | G7: Femenino | H7: Inicio | I7: 2024 | J7: =IFERROR(__xludf.DUMMYFUNCTION("FILTER('CLASFICACIÓN'!$F$3:$F2419,'CLASFICACIÓN'!$G$3:$G2419=M7)"),"SOLO 2024") -> SOLO 2024 | K7: PADD 2023 Y 2024 | L7: 14924 DANIEL ALCIDES CARRION | M7: =E7&D7 -> 14924 DANIEL ALCIDES CARRION4 Primaria
A8: 7 | B8: 48. Piura | C8: Primaria | D8: 4 Primaria | E8: =IFERROR(__xludf.DUMMYFUNCTION("FILTER(Colegios!$B$2:$B2419,Colegios!$A$2:$A2419=L8)"),"14924 DANIEL ALCIDES CARRION") -> 14924 DANIEL ALCIDES CARRION | F8: Rural | G8: Femenino | H8: Inicio | I8: 2024 | J8: =IFERROR(__xludf.DUMMYFUNCTION("FILTER('CLASFICACIÓN'!$F$3:$F2419,'CLASFICACIÓN'!$G$3:$G2419=M8)"),"SOLO 2024") -> SOLO 2024 | K8: PADD 2023 Y 2024 | L8: 14924 DANIEL ALCIDES CARRION | M8: =E8&D8 -> 14924 DANIEL ALCIDES CARRION4 Primaria
A9: 8 | B9: 48. Piura | C9: Primaria | D9: 4 Primaria | E9: =IFERROR(__xludf.DUMMYFUNCTION("FILTER(Colegios!$B$2:$B2419,Colegios!$A$2:$A2419=L9)"),"14924 DANIEL ALCIDES CARRION") -> 14924 DANIEL ALCIDES CARRION | F9: Rural | G9: Femenino | H9: Inicio | I9: 2024 | J9: =IFERROR(__xludf.DUMMYFUNCTION("FILTER('CLASFICACIÓN'!$F$3:$F2419,'CLASFICACIÓN'!$G$3:$G2419=M9)"),"SOLO 2024") -> SOLO 2024 | K9: PADD 2023 Y 2024 | L9: 14924 DANIEL ALCIDES CARRION | M9: =E9&D9 -> 14924 DANIEL ALCIDES CARRION4 Primaria
A10: 9 | B10: 48. Piura | C10: Primaria | D10: 4 Primaria | E10: =IFERROR(__xludf.DUMMYFUNCTION("FILTER(Colegios!$B$2:$B2419,Colegios!$A$2:$A2419=L10)"),"14924 DANIEL ALCIDES CARRION") -> 14924 DANIEL ALCIDES CARRION | F10: Rural | G10: Masculino | H10: Proceso | I10: 2024 | J10: =IFERROR(__xludf.DUMMYFUNCTION("FILTER('CLASFICACIÓN'!$F$3:$F2419,'CLASFICACIÓN'!$G$3:$G2419=M10)"),"SOLO 2024") -> SOLO 2024 | K10: PADD 2023 Y 2024 | L10: 14924 DANIEL ALCIDES CARRION | M10: =E10&D10 -> 14924 DANIEL ALCIDES CARRION4 Primaria
A11: 10 | B11: 48. Piura | C11: Primaria | D11: 4 Primaria | E11: =IFERROR(__xludf.DUMMYFUNCTION("FILTER(Colegios!$B$2:$B2419,Colegios!$A$2:$A2419=L11)"),"14924 DANIEL ALCIDES CARRION") -> 14924 DANIEL ALCIDES CARRION | F11: Rural | G11: Femenino | H11: Satisfactorio | I11: 2024 | J11: =IFERROR(__xludf.DUMMYFUNCTION("FILTER('CLASFICACIÓN'!$F$3:$F2419,'CLASFICACIÓN'!$G$3:$G2419=M11)"),"SOLO 2024") -> SOLO 2024 | K11: PADD 2023 Y 2024 | L11: 14924 DANIEL ALCIDES CARRION | M11: =E11&D11 -> 14924 DANIEL ALCIDES CARRION4 Primaria
A12: 11 | B12: 48. Piura | C12: Primaria | D12: 4 Primaria | E12: =IFERROR(__xludf.DUMMYFUNCTION("FILTER(Colegios!$B$2:$B2419,Colegios!$A$2:$A2419=L12)"),"14924 DANIEL ALCIDES CARRION") -> 14924 DANIEL ALCIDES CARRION | F12: Rural | G12: Masculino | H12: Proceso | I12: 2024 | J12: =IFERROR(__xludf.DUMMYFUNCTION("FILTER('CLASFICACIÓN'!$F$3:$F2419,'CLASFICACIÓN'!$G$3:$G2419=M12)"),"SOLO 2024") -> SOLO 2024 | K12: PADD 2023 Y 2024 | L12: 14924 DANIEL ALCIDES CARRION | M12: =E12&D12 -> 14924 DANIEL ALCIDES CARRION4 Primaria
A13: 12 | B13: 48. Piura | C13: Primaria | D13: 4 Primaria | E13: =IFERROR(__xludf.DUMMYFUNCTION("FILTER(Colegios!$B$2:$B2419,Colegios!$A$2:$A2419=L13)"),"14924 DANIEL ALCIDES CARRION") -> 14924 DANIEL ALCIDES CARRION | F13: Rural | G13: Femenino | H13: Inicio | I13: 2024 | J13: =IFERROR(__xludf.DUMMYFUNCTION("FILTER('CLASFICACIÓN'!$F$3:$F2419,'CLASFICACIÓN'!$G$3:$G2419=M13)"),"SOLO 2024") -> SOLO 2024 | K13: PADD 2023 Y 2024 | L13: 14924 DANIEL ALCIDES CARRION | M13: =E13&D13 -> 14924 DANIEL ALCIDES CARRION4 Primaria
A14: 13 | B14: 48. Piura | C14: Primaria | D14: 4 Primaria | E14: =IFERROR(__xludf.DUMMYFUNCTION("FILTER(Colegios!$B$2:$B2419,Colegios!$A$2:$A2419=L14)"),"14924 DANIEL ALCIDES CARRION") -> 14924 DANIEL ALCIDES CARRION | F14: Rural | G14: Femenino | H14: Inicio | I14: 2024 | J14: =IFERROR(__xludf.DUMMYFUNCTION("FILTER('CLASFICACIÓN'!$F$3:$F2419,'CLASFICACIÓN'!$G$3:$G2419=M14)"),"SOLO 2024") -> SOLO 2024 | K14: PADD 2023 Y 2024 | L14: 14924 DANIEL ALCIDES CARRION | M14: =E14&D14 -> 14924 DANIEL ALCIDES CARRION4 Primaria
A15: 14 | B15: 48. Piura | C15: Primaria | D15: 4 Primaria | E15: =IFERROR(__xludf.DUMMYFUNCTION("FILTER(Colegios!$B$2:$B2419,Colegios!$A$2:$A2419=L15)"),"14924 DANIEL ALCIDES CARRION") -> 14924 DANIEL ALCIDES CARRION | F15: Rural | G15: Femenino | H15: Proceso | I15: 2024 | J15: =IFERROR(__xludf.DUMMYFUNCTION("FILTER('CLASFICACIÓN'!$F$3:$F2419,'CLASFICACIÓN'!$G$3:$G2419=M15)"),"SOLO 2024") -> SOLO 2024 | K15: PADD 2023 Y 2024 | L15: 14924 DANIEL ALCIDES CARRION | M15: =E15&D15 -> 14924 DANIEL ALCIDES CARRION4 Primaria
A16: 15 | B16: 48. Piura | C16: Primaria | D16: 4 Primaria | E16: =IFERROR(__xludf.DUMMYFUNCTION("FILTER(Colegios!$B$2:$B2419,Colegios!$A$2:$A2419=L16)"),"14924 DANIEL ALCIDES CARRION") -> 14924 DANIEL ALCIDES CARRION | F16: Rural | G16: Masculino | H16: Inicio | I16: 2024 | J16: =IFERROR(__xludf.DUMMYFUNCTION("FILTER('CLASFICACIÓN'!$F$3:$F2419,'CLASFICACIÓN'!$G$3:$G2419=M16)"),"SOLO 2024") -> SOLO 2024 | K16: PADD 2023 Y 2024 | L16: 14924 DANIEL ALCIDES CARRION | M16: =E16&D16 -> 14924 DANIEL ALCIDES CARRION4 Primaria
A17: 16 | B17: 48. Piura | C17: Primaria | D17: 4 Primaria | E17: =IFERROR(__xludf.DUMMYFUNCTION("FILTER(Colegios!$B$2:$B2419,Colegios!$A$2:$A2419=L17)"),"14924 DANIEL ALCIDES CARRION") -> 14924 DANIEL ALCIDES CARRION | F17: Rural | G17: Masculino | H17: Inicio | I17: 2024 | J17: =IFERROR(__xludf.DUMMYFUNCTION("FILTER('CLASFICACIÓN'!$F$3:$F2419,'CLASFICACIÓN'!$G$3:$G2419=M17)"),"SOLO 2024") -> SOLO 2024 | K17: PADD 2023 Y 2024 | L17: 14924 DANIEL ALCIDES CARRION | M17: =E17&D17 -> 14924 DANIEL ALCIDES CARRION4 Primaria
A18: 17 | B18: 48. Piura | C18: Primaria | D18: 4 Primaria | E18: =IFERROR(__xludf.DUMMYFUNCTION("FILTER(Colegios!$B$2:$B2419,Colegios!$A$2:$A2419=L18)"),"14924 DANIEL ALCIDES CARRION") -> 14924 DANIEL ALCIDES CARRION | F18: Rural | G18: Femenino | H18: Inicio | I18: 2024 | J18: =IFERROR(__xludf.DUMMYFUNCTION("FILTER('CLASFICACIÓN'!$F$3:$F2419,'CLASFICACIÓN'!$G$3:$G2419=M18)"),"SOLO 2024") -> SOLO 2024 | K18: PADD 2023 Y 2024 | L18: 14924 DANIEL ALCIDES CARRION | M18: =E18&D18 -> 14924 DANIEL ALCIDES CARRION4 Primaria
A19: 18 | B19: 48. Piura | C19: Primaria | D19: 4 Primaria | E19: =IFERROR(__xludf.DUMMYFUNCTION("FILTER(Colegios!$B$2:$B2419,Colegios!$A$2:$A2419=L19)"),"14924 DANIEL ALCIDES CARRION") -> 14924 DANIEL ALCIDES CARRION | F19: Rural | G19: Femenino | H19: Satisfactorio | I19: 2024 | J19: =IFERROR(__xludf.DUMMYFUNCTION("FILTER('CLASFICACIÓN'!$F$3:$F2419,'CLASFICACIÓN'!$G$3:$G2419=M19)"),"SOLO 2024") -> SOLO 2024 | K19: PADD 2023 Y 2024 | L19: 14924 DANIEL ALCIDES CARRION | M19: =E19&D19 -> 14924 DANIEL ALCIDES CARRION4 Primaria
A20: 19 | B20: 48. Piura | C20: Primaria | D20: 4 Primaria | E20: =IFERROR(__xludf.DUMMYFUNCTION("FILTER(Colegios!$B$2:$B2419,Colegios!$A$2:$A2419=L20)"),"14924 DANIEL ALCIDES CARRION") -> 14924 DANIEL ALCIDES CARRION | F20: Rural | G20: Femenino | H20: Inicio | I20: 2024 | J20: =IFERROR(__xludf.DUMMYFUNCTION("FILTER('CLASFICACIÓN'!$F$3:$F2419,'CLASFICACIÓN'!$G$3:$G2419=M20)"),"SOLO 2024") -> SOLO 2024 | K20: PADD 2023 Y 2024 | L20: 14924 DANIEL ALCIDES CARRION | M20: =E20&D20 -> 14924 DANIEL ALCIDES CARRION4 Primaria
A21: 20 | B21: 48. Piura | C21: Primaria | D21: 4 Primaria | E21: =IFERROR(__xludf.DUMMYFUNCTION("FILTER(Colegios!$B$2:$B2419,Colegios!$A$2:$A2419=L21)"),"14924 DANIEL ALCIDES CARRION") -> 14924 DANIEL ALCIDES CARRION | F21: Rural | G21: Masculino | H21: Inicio | I21: 2024 | J21: =IFERROR(__xludf.DUMMYFUNCTION("FILTER('CLASFICACIÓN'!$F$3:$F2419,'CLASFICACIÓN'!$G$3:$G2419=M21)"),"SOLO 2024") -> SOLO 2024 | K21: PADD 2023 Y 2024 | L21: 14924 DANIEL ALCIDES CARRION | M21: =E21&D21 -> 14924 DANIEL ALCIDES CARRION4 Primaria
A22: 21 | B22: 48. Piura | C22: Primaria | D22: 4 Primaria | E22: =IFERROR(__xludf.DUMMYFUNCTION("FILTER(Colegios!$B$2:$B2419,Colegios!$A$2:$A2419=L22)"),"14924 DANIEL ALCIDES CARRION") -> 14924 DANIEL ALCIDES CARRION | F22: Rural | G22: Masculino | H22: Inicio | I22: 2024 | J22: =IFERROR(__xludf.DUMMYFUNCTION("FILTER('CLASFICACIÓN'!$F$3:$F2419,'CLASFICACIÓN'!$G$3:$G2419=M22)"),"SOLO 2024") -> SOLO 2024 | K22: PADD 2023 Y 2024 | L22: 14924 DANIEL ALCIDES CARRION | M22: =E22&D22 -> 14924 DANIEL ALCIDES CARRION4 Primaria
A23: 22 | B23: 48. Piura | C23: Primaria | D23: 4 Primaria | E23: =IFERROR(__xludf.DUMMYFUNCTION("FILTER(Colegios!$B$2:$B2419,Colegios!$A$2:$A2419=L23)"),"14924 DANIEL ALCIDES CARRION") -> 14924 DANIEL ALCIDES CARRION | F23: Rural | G23: Masculino | H23: Inicio | I23: 2024 | J23: =IFERROR(__xludf.DUMMYFUNCTION("FILTER('CLASFICACIÓN'!$F$3:$F2419,'CLASFICACIÓN'!$G$3:$G2419=M23)"),"SOLO 2024") -> SOLO 2024 | K23: PADD 2023 Y 2024 | L23: 14924 DANIEL ALCIDES CARRION | M23: =E23&D23 -> 14924 DANIEL ALCIDES CARRION4 Primaria
A24: 23 | B24: 48. Piura | C24: Primaria | D24: 4 Primaria | E24: =IFERROR(__xludf.DUMMYFUNCTION("FILTER(Colegios!$B$2:$B2419,Colegios!$A$2:$A2419=L24)"),"20104") -> 20104 | F24: Rural | G24: Masculino | H24: Inicio | I24: 2024 | J24: =IFERROR(__xludf.DUMMYFUNCTION("FILTER('CLASFICACIÓN'!$F$3:$F2419,'CLASFICACIÓN'!$G$3:$G2419=M24)"),"SOLO 2024") -> SOLO 2024 | K24: PADD 2023 Y 2024 | L24: 20104 | M24: =E24&D24 -> 201044 Primaria
A25: 24 | B25: 48. Piura | C25: Primaria | D25: 4 Primaria | E25: =IFERROR(__xludf.DUMMYFUNCTION("FILTER(Colegios!$B$2:$B2419,Colegios!$A$2:$A2419=L25)"),"20104") -> 20104 | F25: Rural | G25: Masculino | H25: Inicio | I25: 2024 | J25: =IFERROR(__xludf.DUMMYFUNCTION("FILTER('CLASFICACIÓN'!$F$3:$F2419,'CLASFICACIÓN'!$G$3:$G2419=M25)"),"SOLO 2024") -> SOLO 2024 | K25: PADD 2023 Y 2024 | L25: 20104 | M25: =E25&D25 -> 201044 Primaria
A26: 25 | B26: 48. Piura | C26: Primaria | D26: 4 Primaria | E26: =IFERROR(__xludf.DUMMYFUNCTION("FILTER(Colegios!$B$2:$B2419,Colegios!$A$2:$A2419=L26)"),"20104") -> 20104 | F26: Rural | G26: Masculino | H26: Inicio | I26: 2024 | J26: =IFERROR(__xludf.DUMMYFUNCTION("FILTER('CLASFICACIÓN'!$F$3:$F2419,'CLASFICACIÓN'!$G$3:$G2419=M26)"),"SOLO 2024") -> SOLO 2024 | K26: PADD 2023 Y 2024 | L26: 20104 | M26: =E26&D26 -> 201044 Primaria
A27: 26 | B27: 48. Piura | C27: Primaria | D27: 4 Primaria | E27: =IFERROR(__xludf.DUMMYFUNCTION("FILTER(Colegios!$B$2:$B2419,Colegios!$A$2:$A2419=L27)"),"20104") -> 20104 | F27: Rural | G27: Masculino | H27: Inicio | I27: 2024 | J27: =IFERROR(__xludf.DUMMYFUNCTION("FILTER('CLASFICACIÓN'!$F$3:$F2419,'CLASFICACIÓN'!$G$3:$G2419=M27)"),"SOLO 2024") -> SOLO 2024 | K27: PADD 2023 Y 2024 | L27: 20104 | M27: =E27&D27 -> 201044 Primaria
A28: 27 | B28: 48. Piura | C28: Primaria | D28: 4 Primaria | E28: =IFERROR(__xludf.DUMMYFUNCTION("FILTER(Colegios!$B$2:$B2419,Colegios!$A$2:$A2419=L28)"),"20104") -> 20104 | F28: Rural | G28: Femenino | H28: Inicio | I28: 2024 | J28: =IFERROR(__xludf.DUMMYFUNCTION("FILTER('CLASFICACIÓN'!$F$3:$F2419,'CLASFICACIÓN'!$G$3:$G2419=M28)"),"SOLO 2024") -> SOLO 2024 | K28: PADD 2023 Y 2024 | L28: 20104 | M28: =E28&D28 -> 201044 Primaria
A29: 28 | B29: 48. Piura | C29: Primaria | D29: 4 Primaria | E29: =IFERROR(__xludf.DUMMYFUNCTION("FILTER(Colegios!$B$2:$B2419,Colegios!$A$2:$A2419=L29)"),"20104") -> 20104 | F29: Rural | G29: Femenino | H29: Inicio | I29: 2024 | J29: =IFERROR(__xludf.DUMMYFUNCTION("FILTER('CLASFICACIÓN'!$F$3:$F2419,'CLASFICACIÓN'!$G$3:$G2419=M29)"),"SOLO 2024") -> SOLO 2024 | K29: PADD 2023 Y 2024 | L29: 20104 | M29: =E29&D29 -> 201044 Primaria
A30: 29 | B30: 48. Piura | C30: Primaria | D30: 4 Primaria | E30: =IFERROR(__xludf.DUMMYFUNCTION("FILTER(Colegios!$B$2:$B2419,Colegios!$A$2:$A2419=L30)"),"20104") -> 20104 | F30: Rural | G30: Femenino | H30: Inicio | I30: 2024 | J30: =IFERROR(__xludf.DUMMYFUNCTION("FILTER('CLASFICACIÓN'!$F$3:$F2419,'CLASFICACIÓN'!$G$3:$G2419=M30)"),"SOLO 2024") -> SOLO 2024 | K30: PADD 2023 Y 2024 | L30: 20104 | M30: =E30&D30 -> 201044 Primaria
A31: 30 | B31: 48. Piura | C31: Primaria | D31: 4 Primaria | E31: =IFERROR(__xludf.DUMMYFUNCTION("FILTER(Colegios!$B$2:$B2419,Colegios!$A$2:$A2419=L31)"),"14975") -> 14975 | F31: Rural | G31: Masculino | H31: Inicio | I31: 2024 | J31: =IFERROR(__xludf.DUMMYFUNCTION("FILTER('CLASFICACIÓN'!$F$3:$F2419,'CLASFICACIÓN'!$G$3:$G2419=M31)"),"SOLO 2024") -> SOLO 2024 | K31: PADD 2023 Y 2024 | L31: 14975 | M31: =E31&D31 -> 149754 Primaria
A32: 31 | B32: 48. Piura | C32: Primaria | D32: 4 Primaria | E32: =IFERROR(__xludf.DUMMYFUNCTION("FILTER(Colegios!$B$2:$B2419,Colegios!$A$2:$A2419=L32)"),"14975") -> 14975 | F32: Rural | G32: Masculino | H32: Inicio | I32: 2024 | J32: =IFERROR(__xludf.DUMMYFUNCTION("FILTER('CLASFICACIÓN'!$F$3:$F2419,'CLASFICACIÓN'!$G$3:$G2419=M32)"),"SOLO 2024") -> SOLO 2024 | K32: PADD 2023 Y 2024 | L32: 14975 | M32: =E32&D32 -> 149754 Primaria
A33: 32 | B33: 48. Piura | C33: Primaria | D33: 4 Primaria | E33: =IFERROR(__xludf.DUMMYFUNCTION("FILTER(Colegios!$B$2:$B2419,Colegios!$A$2:$A2419=L33)"),"14975") -> 14975 | F33: Rural | G33: Masculino | H33: Proceso | I33: 2024 | J33: =IFERROR(__xludf.DUMMYFUNCTION("FILTER('CLASFICACIÓN'!$F$3:$F2419,'CLASFICACIÓN'!$G$3:$G2419=M33)"),"SOLO 2024") -> SOLO 2024 | K33: PADD 2023 Y 2024 | L33: 14975 | M33: =E33&D33 -> 149754 Primaria
A34: 33 | B34: 48. Piura | C34: Primaria | D34: 4 Primaria | E34: =IFERROR(__xludf.DUMMYFUNCTION("FILTER(Colegios!$B$2:$B2419,Colegios!$A$2:$A2419=L34)"),"14975") -> 14975 | F34: Rural | G34: Femenino | H34: Inicio | I34: 2024 | J34: =IFERROR(__xludf.DUMMYFUNCTION("FILTER('CLASFICACIÓN'!$F$3:$F2419,'CLASFICACIÓN'!$G$3:$G2419=M34)"),"SOLO 2024") -> SOLO 2024 | K34: PADD 2023 Y 2024 | L34: 14975 | M34: =E34&D34 -> 149754 Primaria
A35: 34 | B35: 48. Piura | C35: Primaria | D35: 4 Primaria | E35: =IFERROR(__xludf.DUMMYFUNCTION("FILTER(Colegios!$B$2:$B2419,Colegios!$A$2:$A2419=L35)"),"14975") -> 14975 | F35: Rural | G35: Femenino | H35: Inicio | I35: 2024 | J35: =IFERROR(__xludf.DUMMYFUNCTION("FILTER('CLASFICACIÓN'!$F$3:$F2419,'CLASFICACIÓN'!$G$3:$G2419=M35)"),"SOLO 2024") -> SOLO 2024 | K35: PADD 2023 Y 2024 | L35: 14975 | M35: =E35&D35 -> 149754 Primaria
A36: 35 | B36: 48. Piura | C36: Primaria | D36: 4 Primaria | E36: =IFERROR(__xludf.DUMMYFUNCTION("FILTER(Colegios!$B$2:$B2419,Colegios!$A$2:$A2419=L36)"),"14975") -> 14975 | F36: Rural | G36: Femenino | H36: Proceso | I36: 2024 | J36: =IFERROR(__xludf.DUMMYFUNCTION("FILTER('CLASFICACIÓN'!$F$3:$F2419,'CLASFICACIÓN'!$G$3:$G2419=M36)"),"SOLO 2024") -> SOLO 2024 | K36: PADD 2023 Y 2024 | L36: 14975 | M36: =E36&D36 -> 149754 Primaria
A37: 36 | B37: 48. Piura | C37: Primaria | D37: 4 Primaria | E37: =IFERROR(__xludf.DUMMYFUNCTION("FILTER(Colegios!$B$2:$B2419,Colegios!$A$2:$A2419=L37)"),"15304") -> 15304 | F37: Rural | G37: Masculino | H37: Inicio | I37: 2024 | J37: =IFERROR(__xludf.DUMMYFUNCTION("FILTER('CLASFICACIÓN'!$F$3:$F2419,'CLASFICACIÓN'!$G$3:$G2419=M37)"),"2023 Y 2024") -> 2023 Y 2024 | K37: SOLO 2023 | L37: 15304 | M37: =E37&D37 -> 153044 Primaria
A38: 37 | B38: 48. Piura | C38: Primaria | D38: 4 Primaria | E38: =IFERROR(__xludf.DUMMYFUNCTION("FILTER(Colegios!$B$2:$B2419,Colegios!$A$2:$A2419=L38)"),"15304") -> 15304 | F38: Rural | G38: Masculino | H38: Inicio | I38: 2024 | J38: =IFERROR(__xludf.DUMMYFUNCTION("FILTER('CLASFICACIÓN'!$F$3:$F2419,'CLASFICACIÓN'!$G$3:$G2419=M38)"),"2023 Y 2024") -> 2023 Y 2024 | K38: SOLO 2023 | L38: 15304 | M38: =E38&D38 -> 153044 Primaria
A39: 38 | B39: 48. Piura | C39: Primaria | D39: 4 Primaria | E39: =IFERROR(__xludf.DUMMYFUNCTION("FILTER(Colegios!$B$2:$B2419,Colegios!$A$2:$A2419=L39)"),"SAGRADO CORAZON DE JESUS") -> SAGRADO CORAZON DE JESUS | F39: Rural | G39: Masculino | H39: Inicio | I39: 2024 | J39: =IFERROR(__xludf.DUMMYFUNCTION("FILTER('CLASFICACIÓN'!$F$3:$F2419,'CLASFICACIÓN'!$G$3:$G2419=M39)"),"2023 Y 2024") -> 2023 Y 2024 | K39: NO PARTICIPÓ | L39: SAGRADO CORAZON DE JESUS | M39: =E39&D39 -> SAGRADO CORAZON DE JESUS4 Primaria
A40: 39 | B40: 48. Piura | C40: Primaria | D40: 4 Primaria | E40: =IFERROR(__xludf.DUMMYFUNCTION("FILTER(Colegios!$B$2:$B2419,Colegios!$A$2:$A2419=L40)"),"SAGRADO CORAZON DE JESUS") -> SAGRADO CORAZON DE JESUS | F40: Rural | G40: Masculino | H40: Inicio | I40: 2024 | J40: =IFERROR(__xludf.DUMMYFUNCTION("FILTER('CLASFICACIÓN'!$F$3:$F2419,'CLASFICACIÓN'!$G$3:$G2419=M40)"),"2023 Y 2024") -> 2023 Y 2024 | K40: NO PARTICIPÓ | L40: SAGRADO CORAZON DE JESUS | M40: =E40&D40 -> SAGRADO CORAZON DE JESUS4 Primaria
...

Sheet 1° primaria
A1: Estudiante | B1: Región | C1: Nivel | D1: Grado | E1: Institución Educativa | F1: Ambito | G1: Sexo | H1: R Producción de textos | I1: Año | K1: ID IE | AH1: Año | AI1: #
A2: 1 | B2: 48. Piura | C2: Primaria | D2: 4 Primaria | E2: 14924 DANIEL ALCIDES CARRION | F2: Rural | G2: Masculino | H2: Inicio | I2: 2024 | K2: 14924 DANIEL ALCIDES CARRION | M2: =(SUMA(H3:S3)/BDEXTRAER(claves!$A$2:$I$8,claves!$I$2,{claves!$B$2;D3}))*50 | AI2: =COUNTA(A2:A2333) -> 2332
A3: 2 | B3: 48. Piura | C3: Primaria | D3: 4 Primaria | E3: 14924 DANIEL ALCIDES CARRION | F3: Rural | G3: Masculino | H3: Inicio | I3: 2024 | K3: 14924 DANIEL ALCIDES CARRION
A4: 3 | B4: 48. Piura | C4: Primaria | D4: 4 Primaria | E4: 14924 DANIEL ALCIDES CARRION | F4: Rural | G4: Masculino | H4: Proceso | I4: 2024 | K4: 14924 DANIEL ALCIDES CARRION
A5: 4 | B5: 48. Piura | C5: Primaria | D5: 4 Primaria | E5: 14924 DANIEL ALCIDES CARRION | F5: Rural | G5: Femenino | H5: Proceso | I5: 2024 | K5: 14924 DANIEL ALCIDES CARRION
A6: 5 | B6: 48. Piura | C6: Primaria | D6: 4 Primaria | E6: 14924 DANIEL ALCIDES CARRION | F6: Rural | G6: Masculino | H6: Proceso | I6: 2024 | K6: 14924 DANIEL ALCIDES CARRION
A7: 6 | B7: 48. Piura | C7: Primaria | D7: 4 Primaria | E7: 14924 DANIEL ALCIDES CARRION | F7: Rural | G7: Femenino | H7: Inicio | I7: 2024 | K7: 14924 DANIEL ALCIDES CARRION
A8: 7 | B8: 48. Piura | C8: Primaria | D8: 4 Primaria | E8: 14924 DANIEL ALCIDES CARRION | F8: Rural | G8: Femenino | H8: Inicio | I8: 2024 | K8: 14924 DANIEL ALCIDES CARRION
A9: 8 | B9: 48. Piura | C9: Primaria | D9: 4 Primaria | E9: 14924 DANIEL ALCIDES CARRION | F9: Rural | G9: Femenino | H9: Inicio | I9: 2024 | K9: 14924 DANIEL ALCIDES CARRION
A10: 9 | B10: 48. Piura | C10: Primaria | D10: 4 Primaria | E10: 14924 DANIEL ALCIDES CARRION | F10: Rural | G10: Masculino | H10: Proceso | I10: 2024 | K10: 14924 DANIEL ALCIDES CARRION
A11: 10 | B11: 48. Piura | C11: Primaria | D11: 4 Primaria | E11: 14924 DANIEL ALCIDES CARRION | F11: Rural | G11: Femenino | H11: Satisfactorio | I11: 2024 | K11: 14924 DANIEL ALCIDES CARRION
A12: 11 | B12: 48. Piura | C12: Primaria | D12: 4 Primaria | E12: 14924 DANIEL ALCIDES CARRION | F12: Rural | G12: Masculino | H12: Proceso | I12: 2024 | K12: 14924 DANIEL ALCIDES CARRION
A13: 12 | B13: 48. Piura | C13: Primaria | D13: 4 Primaria | E13: 14924 DANIEL ALCIDES CARRION | F13: Rural | G13: Femenino | H13: Inicio | I13: 2024 | K13: 14924 DANIEL ALCIDES CARRION
A14: 13 | B14: 48. Piura | C14: Primaria | D14: 4 Primaria | E14: 14924 DANIEL ALCIDES CARRION | F14: Rural | G14: Femenino | H14: Inicio | I14: 2024 | K14: 14924 DANIEL ALCIDES CARRION
... A23: 22 | B23: 48. Piura | C23: Primaria | D23: 4 Primaria | E23: 14924 DANIEL ALCIDES CARRION | F23: Rural | G23: Masculino | H23: Inicio | I23: 2024 | K23: 14924 DANIEL ALCIDES CARRION
A24: 23 | B24: 48. Piura | C24: Primaria | D24: 4 Primaria | E24: 20104 | F24: Rural | G24: Masculino | H24: Inicio | I24: 2024 | K24: 20104
A25: 24 | B25: 48. Piura | C25: Primaria | D25: 4 Primaria | E25: 20104 | F25: Rural | G25: Masculino | H25: Inicio | I25: 2024 | K25: 20104
A26: 25 | B26: 48. Piura | C26: Primaria | D26: 4 Primaria | E26: 20104 | F26: Rural | G26: Masculino | H26: Inicio | I26: 2024 | K26: 20104
A27: 26 | B27: 48. Piura | C27: Primaria | D27: 4 Primaria | E27: 20104 | F27: Rural | G27: Masculino | H27: Inicio | I27: 2024 | K27: 20104
A28: 27 | B28: 48. Piura | C28: Primaria | D28: 4 Primaria | E28: 20104 | F28: Rural | G28: Femenino | H28: Inicio | I28: 2024 | K28: 20104
A29: 28 | B29: 48. Piura | C29: Primaria | D29: 4 Primaria | E29: 20104 | F29: Rural | G29: Femenino | H29: Inicio | I29: 2024 | K29: 20104
A30: 29 | B30: 48. Piura | C30: Primaria | D30: 4 Primaria | E30: 20104 | F30: Rural | G30: Femenino | H30: Inicio | I30: 2024 | K30: 20104
A31: 30 | B31: 48. Piura | C31: Primaria | D31: 4 Primaria | E31: 14975 | F31: Rural | G31: Masculino | H31: Inicio | I31: 2024 | K31: 14975
A32: 31 | B32: 48. Piura | C32: Primaria | D32: 4 Primaria | E32: 14975 | F32: Rural | G32: Masculino | H32: Inicio | I32: 2024 | K32: 14975
A33: 32 | B33: 48. Piura | C33: Primaria | D33: 4 Primaria | E33: 14975 | F33: Rural | G33: Masculino | H33: Proceso | I33: 2024 | K33: 14975
A34: 33 | B34: 48. Piura | C34: Primaria | D34: 4 Primaria | E34: 14975 | F34: Rural | G34: Femenino | H34: Inicio | I34: 2024 | K34: 14975
A35: 34 | B35: 48. Piura | C35: Primaria | D35: 4 Primaria | E35: 14975 | F35: Rural | G35: Femenino | H35: Inicio | I35: 2024 | K35: 14975
... A38: 37 | B38: 48. Piura | C38: Primaria | D38: 4 Primaria | E38: 15304 | F38: Rural | G38: Masculino | H38: Inicio | I38: 2024 | K38: 15304
A39: 38 | B39: 48. Piura | C39: Primaria | D39: 4 Primaria | E39: SAGRADO CORAZON DE JESUS | F39: Rural | G39: Masculino | H39: Inicio | I39: 2024 | K39: SAGRADO CORAZON DE JESUS
A40: 39 | B40: 48. Piura | C40: Primaria | D40: 4 Primaria | E40: SAGRADO CORAZON DE JESUS | F40: Rural | G40: Masculino | H40: Inicio | I40: 2024 | K40: SAGRADO CORAZON DE JESUS
A41: 40 | B41: 48. Piura | C41: Primaria | D41: 4 Primaria | E41: SAGRADO CORAZON DE JESUS | F41: Rural | G41: Masculino | H41: Inicio | I41: 2024 | K41: SAGRADO CORAZON DE JESUS
A42: 41 | B42: 48. Piura | C42: Primaria | D42: 4 Primaria | E42: SAGRADO CORAZON DE JESUS | F42: Rural | G42: Masculino | H42: Inicio | I42: 2024 | K42: SAGRADO CORAZON DE JESUS
A43: 42 | B43: 48. Piura | C43: Primaria | D43: 4 Primaria | E43: SAGRADO CORAZON DE JESUS | F43: Rural | G43: Femenino | H43: Inicio | I43: 2024 | K43: SAGRADO CORAZON DE JESUS
A44: 43 | B44: 48. Piura | C44: Primaria | D44: 4 Primaria | E44: SAGRADO CORAZON DE JESUS | F44: Rural | G44: Femenino | H44: Inicio | I44: 2024 | K44: SAGRADO CORAZON DE JESUS
A45: 44 | B45: 48. Piura | C45: Primaria | D45: 4 Primaria | E45: SAGRADO CORAZON DE JESUS | F45: Rural | G45: Femenino | H45: Inicio | I45: 2024 | K45: SAGRADO CORAZON DE JESUS
A46: 45 | B46: 48. Piura | C46: Primaria | D46: 4 Primaria | E46: 14144 SANTA ROSA | F46: Rural | G46: Femenino | H46: Proceso | I46: 2024 | K46: 14144 SANTA ROSA
A47: 46 | B47: 48. Piura | C47: Primaria | D47: 4 Primaria | E47: 14144 SANTA ROSA | F47: Rural | G47: Femenino | H47: Inicio | I47: 2024 | K47: 14144 SANTA ROSA
A48: 47 | B48: 48. Piura | C48: Primaria | D48: 4 Primaria | E48: 14144 SANTA ROSA | F48: Rural | G48: Femenino | H48: Inicio | I48: 2024 | K48: 14144 SANTA ROSA
A49: 48 | B49: 48. Piura | C49: Primaria | D49: 4 Primaria | E49: 14144 SANTA ROSA | F49: Rural | G49: Femenino | H49: Proceso | I49: 2024 | K49: 14144 SANTA ROSA
A50: 49 | B50: 48. Piura | C50: Primaria | D50: 4 Primaria | E50: 14144 SANTA ROSA | F50: Rural | G50: Masculino | H50: Inicio | I50: 2024 | K50: 14144 SANTA ROSA
...

Sheet Colegios
A1: =IFERROR(__xludf.DUMMYFUNCTION("IMPORTRANGE(""https://docs.google.com/spreadsheets/d/1G0lKhjdDNZcuaaQlGltXi5PoiboQrtAFuEFhYlQNIWs/edit?gid=1917248718#gid=1917248718"",""Colegios!A1:D"")"),"Institución Educativa") -> Institución Educativa | B1: =IFERROR(__xludf.DUMMYFUNCTION("""COMPUTED_VALUE"""),"Nombre a reemplazar") -> Nombre a reemplazar | C1: =IFERROR(__xludf.DUMMYFUNCTION("""COMPUTED_VALUE"""),"Región") -> Región | D1: =IFERROR(__xludf.DUMMYFUNCTION("""COMPUTED_VALUE"""),"Año") -> Año
A2: =IFERROR(__xludf.DUMMYFUNCTION("""COMPUTED_VALUE"""),"Accocunca") -> Accocunca | B2: =IFERROR(__xludf.DUMMYFUNCTION("""COMPUTED_VALUE"""),"50547") -> 50547
A3: =IFERROR(__xludf.DUMMYFUNCTION("""COMPUTED_VALUE"""),"Andamayo") -> Andamayo | B3: =IFERROR(__xludf.DUMMYFUNCTION("""COMPUTED_VALUE"""),"50977") -> 50977
A4: =IFERROR(__xludf.DUMMYFUNCTION("""COMPUTED_VALUE"""),"Ccapana") -> Ccapana | B4: =IFERROR(__xludf.DUMMYFUNCTION("""COMPUTED_VALUE"""),"50495") -> 50495
A5: =IFERROR(__xludf.DUMMYFUNCTION("""COMPUTED_VALUE"""),"Cristo Rey") -> Cristo Rey | B5: =IFERROR(__xludf.DUMMYFUNCTION("""COMPUTED_VALUE"""),"501455 CRISTO REY TTIKARIY") -> 501455 CRISTO REY TTIKARIY
A6: =IFERROR(__xludf.DUMMYFUNCTION("""COMPUTED_VALUE"""),"Kumuncancha") -> Kumuncancha | B6: =IFERROR(__xludf.DUMMYFUNCTION("""COMPUTED_VALUE"""),"501432 PAPA FRANCISCO I") -> 501432 PAPA FRANCISCO I
A7: =IFERROR(__xludf.DUMMYFUNCTION("""COMPUTED_VALUE"""),"Llachi") -> Llachi | B7: =IFERROR(__xludf.DUMMYFUNCTION("""COMPUTED_VALUE"""),"50715") -> 50715
A8: =IFERROR(__xludf.DUMMYFUNCTION("""COMPUTED_VALUE"""),"Marampaqui") -> Marampaqui | B8: =IFERROR(__xludf.DUMMYFUNCTION("""COMPUTED_VALUE"""),"50553") -> 50553
A9: =IFERROR(__xludf.DUMMYFUNCTION("""COMPUTED_VALUE"""),"Ocongate") -> Ocongate | B9: =IFERROR(__xludf.DUMMYFUNCTION("""COMPUTED_VALUE"""),"50492 CORAZON DE JESUS") -> 50492 CORAZON DE JESUS
A10: =IFERROR(__xludf.DUMMYFUNCTION("""COMPUTED_VALUE"""),"Pampacancha") -> Pampacancha | B10: =IFERROR(__xludf.DUMMYFUNCTION("""COMPUTED_VALUE"""),"50550") -> 50550
A11: =IFERROR(__xludf.DUMMYFUNCTION("""COMPUTED_VALUE"""),"Sallicancha") -> Sallicancha | B11: =IFERROR(__xludf.DUMMYFUNCTION("""COMPUTED_VALUE"""),"50765") -> 50765
A12: =IFERROR(__xludf.DUMMYFUNCTION("""COMPUTED_VALUE"""),"Yanacancha") -> Yanacancha | B12: =IFERROR(__xludf.DUMMYFUNCTION("""COMPUTED_VALUE"""),"50696 YANACANCHA") -> 50696 YANACANCHA
A13: =IFERROR(__xludf.DUMMYFUNCTION("""COMPUTED_VALUE"""),"50492- CORAZON DE JESUS OCONGATE") -> 50492- CORAZON DE JESUS OCONGATE | B13: =IFERROR(__xludf.DUMMYFUNCTION("""COMPUTED_VALUE"""),"50492 CORAZON DE JESUS") -> 50492 CORAZON DE JESUS
A14: =IFERROR(__xludf.DUMMYFUNCTION("""COMPUTED_VALUE"""),"50495 CCAPANA") -> 50495 CCAPANA | B14: =IFERROR(__xludf.DUMMYFUNCTION("""COMPUTED_VALUE"""),"50495") -> 50495
A15: =IFERROR(__xludf.DUMMYFUNCTION("""COMPUTED_VALUE"""),"50547 Accocunca") -> 50547 Accocunca | B15: =IFERROR(__xludf.DUMMYFUNCTION("""COMPUTED_VALUE"""),"50547") -> 50547
A16: =IFERROR(__xludf.DUMMYFUNCTION("""COMPUTED_VALUE"""),"50550 PAMPACANCHA") -> 50550 PAMPACANCHA | B16: =IFERROR(__xludf.DUMMYFUNCTION("""COMPUTED_VALUE"""),"50550") -> 50550
A17: =IFERROR(__xludf.DUMMYFUNCTION("""COMPUTED_VALUE"""),"50552 ""TÚPAC AMARU II"" - HUACATINCO") -> 50552 "TÚPAC AMARU II" - HUACATINCO | B17: =IFERROR(__xludf.DUMMYFUNCTION("""COMPUTED_VALUE"""),"50552 TUPAC AMARU II") -> 50552 TUPAC AMARU II
A18: =IFERROR(__xludf.DUMMYFUNCTION("""COMPUTED_VALUE"""),"50553 MARAMPAQUI") -> 50553 MARAMPAQUI | B18: =IFERROR(__xludf.DUMMYFUNCTION("""COMPUTED_VALUE"""),"50553") -> 50553
A19: =IFERROR(__xludf.DUMMYFUNCTION("""COMPUTED_VALUE"""),"50558 PARCCOCALLA") -> 50558 PARCCOCALLA | B19: =IFERROR(__xludf.DUMMYFUNCTION("""COMPUTED_VALUE"""),"50558") -> 50558
A20: =IFERROR(__xludf.DUMMYFUNCTION("""COMPUTED_VALUE"""),"50715 - Llachi") -> 50715 - Llachi | B20: =IFERROR(__xludf.DUMMYFUNCTION("""COMPUTED_VALUE"""),"50715") -> 50715
A21: =IFERROR(__xludf.DUMMYFUNCTION("""COMPUTED_VALUE"""),"50719- VIRGEN DEL CARMEN TINKE") -> 50719- VIRGEN DEL CARMEN TINKE | B21: =IFERROR(__xludf.DUMMYFUNCTION("""COMPUTED_VALUE"""),"50719 VIRGEN DEL CARMEN") -> 50719 VIRGEN DEL CARMEN
A22: =IFERROR(__xludf.DUMMYFUNCTION("""COMPUTED_VALUE"""),"50765 - SALLICANCHA") -> 50765 - SALLICANCHA | B22: =IFERROR(__xludf.DUMMYFUNCTION("""COMPUTED_VALUE"""),"50765") -> 50765
A23: =IFERROR(__xludf.DUMMYFUNCTION("""COMPUTED_VALUE"""),"50696 YANACANCHA") -> 50696 YANACANCHA | B23: =IFERROR(__xludf.DUMMYFUNCTION("""COMPUTED_VALUE"""),"50696 YANACANCHA") -> 50696 YANACANCHA
A24: =IFERROR(__xludf.DUMMYFUNCTION("""COMPUTED_VALUE"""),"50854 de PATAPALLAPA ALTA") -> 50854 de PATAPALLAPA ALTA | B24: =IFERROR(__xludf.DUMMYFUNCTION("""COMPUTED_VALUE"""),"50854") -> 50854
A25: =IFERROR(__xludf.DUMMYFUNCTION("""COMPUTED_VALUE"""),"50977 Andamayo") -> 50977 Andamayo | B25: =IFERROR(__xludf.DUMMYFUNCTION("""COMPUTED_VALUE"""),"50977") -> 50977
A26: =IFERROR(__xludf.DUMMYFUNCTION("""COMPUTED_VALUE"""),"501344 - CCASAPATA") -> 501344 - CCASAPATA | B26: =IFERROR(__xludf.DUMMYFUNCTION("""COMPUTED_VALUE"""),"501344") -> 501344
A27: =IFERROR(__xludf.DUMMYFUNCTION("""COMPUTED_VALUE"""),"501344- CCASAPATA") -> 501344- CCASAPATA | B27: =IFERROR(__xludf.DUMMYFUNCTION("""COMPUTED_VALUE"""),"501344") -> 501344
A28: =IFERROR(__xludf.DUMMYFUNCTION("""COMPUTED_VALUE"""),"501432 - Kumuncancha") -> 501432 - Kumuncancha | B28: =IFERROR(__xludf.DUMMYFUNCTION("""COMPUTED_VALUE"""),"501432 PAPA FRANCISCO I") -> 501432 PAPA FRANCISCO I
A29: =IFERROR(__xludf.DUMMYFUNCTION("""COMPUTED_VALUE"""),"501455 - CRISTO REY TIKARIY") -> 501455 - CRISTO REY TIKARIY | B29: =IFERROR(__xludf.DUMMYFUNCTION("""COMPUTED_VALUE"""),"501455 CRISTO REY TTIKARIY") -> 501455 CRISTO REY TTIKARIY
A30: =IFERROR(__xludf.DUMMYFUNCTION("""COMPUTED_VALUE"""),"Papa Francisco I") -> Papa Francisco I | B30: =IFERROR(__xludf.DUMMYFUNCTION("""COMPUTED_VALUE"""),"501432 PAPA FRANCISCO I") -> 501432 PAPA FRANCISCO I
A31: =IFERROR(__xludf.DUMMYFUNCTION("""COMPUTED_VALUE"""),"601448") -> 601448 | B31: =IFERROR(__xludf.DUMMYFUNCTION("""COMPUTED_VALUE"""),"601448") -> 601448
A32: =IFERROR(__xludf.DUMMYFUNCTION("""COMPUTED_VALUE"""),"601148") -> 601148 | B32: =IFERROR(__xludf.DUMMYFUNCTION("""COMPUTED_VALUE"""),"601448") -> 601448
A33: =IFERROR(__xludf.DUMMYFUNCTION("""COMPUTED_VALUE"""),"601614") -> 601614 | B33: =IFERROR(__xludf.DUMMYFUNCTION("""COMPUTED_VALUE"""),"601614") -> 601614
A34: =IFERROR(__xludf.DUMMYFUNCTION("""COMPUTED_VALUE"""),"EL MILAGRO") -> EL MILAGRO | B34: =IFERROR(__xludf.DUMMYFUNCTION("""COMPUTED_VALUE"""),"EL MILAGRO") -> EL MILAGRO
A35: =IFERROR(__xludf.DUMMYFUNCTION("""COMPUTED_VALUE"""),"EL MILAGRO ") -> EL MILAGRO | B35: =IFERROR(__xludf.DUMMYFUNCTION("""COMPUTED_VALUE"""),"EL MILAGRO") -> EL MILAGRO
A36: =IFERROR(__xludf.DUMMYFUNCTION("""COMPUTED_VALUE"""),"601514") -> 601514 | B36: =IFERROR(__xludf.DUMMYFUNCTION("""COMPUTED_VALUE"""),"601514") -> 601514
A37: =IFERROR(__xludf.DUMMYFUNCTION("""COMPUTED_VALUE"""),"601331") -> 601331 | B37: =IFERROR(__xludf.DUMMYFUNCTION("""COMPUTED_VALUE"""),"601331") -> 601331
A38: =IFERROR(__xludf.DUMMYFUNCTION("""COMPUTED_VALUE"""),"6010230") -> 6010230 | B38: =IFERROR(__xludf.DUMMYFUNCTION("""COMPUTED_VALUE"""),"6010230 BARBARA D'ACHILLE") -> 6010230 BARBARA D'ACHILLE
A39: =IFERROR(__xludf.DUMMYFUNCTION("""COMPUTED_VALUE"""),"60133") -> 60133 | B39: =IFERROR(__xludf.DUMMYFUNCTION("""COMPUTED_VALUE"""),"60133") -> 60133
A40: =IFERROR(__xludf.DUMMYFUNCTION("""COMPUTED_VALUE"""),"60136 MORALILLO") -> 60136 MORALILLO | B40: =IFERROR(__xludf.DUMMYFUNCTION("""COMPUTED_VALUE"""),"60136") -> 60136
...

Sheet PADD-R
A1: RER | B1: IIEE | C1: LÍNEA BASE 2022 | D1: LÍNEA BASE 2023 | E1: LÍNEA BASE 2022 | F1: LÍNEA BASE 2023 | G1: LÍNEA BASE 2022 | H1: LÍNEA BASE 2023 | I1: PADD 2023 | J1: PADD 2024 | K1: PADD | L1: ID IIEE
A2: CUSCO - 44 | B2: 501344 | J2: 1 | K2: =IF(AND(I2<>"",J2<>""),"PADD 2023 Y 2024",IF(I2<>"","SOLO 2023",IF(J2<>"","SOLO 2024","NO PARTICIPÓ"))) -> SOLO 2024 | L2: 501344 Ccasapata
A3: CUSCO - 44 | B3: 501455 CRISTO REY TTIKARIY | D3: 1 | F3: 1 | I3: 1 | J3: 1 | K3: =IF(AND(I3<>"",J3<>""),"PADD 2023 Y 2024",IF(I3<>"","SOLO 2023",IF(J3<>"","SOLO 2024","NO PARTICIPÓ"))) -> PADD 2023 Y 2024 | L3: 501455 Cristo Rey Ttikariy- Pacchanta Baja
A4: CUSCO - 44 | B4: 50492 CORAZON DE JESUS | C4: 1 | D4: 1 | E4: 1 | F4: 1 | I4: 1 | J4: 1 | K4: =IF(AND(I4<>"",J4<>""),"PADD 2023 Y 2024",IF(I4<>"","SOLO 2023",IF(J4<>"","SOLO 2024","NO PARTICIPÓ"))) -> PADD 2023 Y 2024 | L4: 50492 "Corazón de Jesús" Ocongate
A5: CUSCO - 44 | B5: 50550 | C5: 1 | D5: 1 | E5: 1 | F5: 1 | I5: 1 | J5: 1 | K5: =IF(AND(I5<>"",J5<>""),"PADD 2023 Y 2024",IF(I5<>"","SOLO 2023",IF(J5<>"","SOLO 2024","NO PARTICIPÓ"))) -> PADD 2023 Y 2024 | L5: 50550 Pampacancha
A6: CUSCO - 44 | B6: 50552 TUPAC AMARU II | J6: 1 | K6: =IF(AND(I6<>"",J6<>""),"PADD 2023 Y 2024",IF(I6<>"","SOLO 2023",IF(J6<>"","SOLO 2024","NO PARTICIPÓ"))) -> SOLO 2024 | L6: 50552 Tupac Amaru II - Huacatinco
A7: CUSCO - 44 | B7: 50558 | C7: 1 | E7: 1 | J7: 1 | K7: =IF(AND(I7<>"",J7<>""),"PADD 2023 Y 2024",IF(I7<>"","SOLO 2023",IF(J7<>"","SOLO 2024","NO PARTICIPÓ"))) -> SOLO 2024 | L7: 50558 Parccocalla
A8: CUSCO - 44 | B8: 50719 VIRGEN DEL CARMEN | C8: 1 | E8: 1 | J8: 1 | K8: =IF(AND(I8<>"",J8<>""),"PADD 2023 Y 2024",IF(I8<>"","SOLO 2023",IF(J8<>"","SOLO 2024","NO PARTICIPÓ"))) -> SOLO 2024 | L8: 50719 Virgen del Carmen de Tinke
A9: CUSCO - 44 | B9: 50854 | C9: 1 | E9: 1 | J9: 1 | K9: =IF(AND(I9<>"",J9<>""),"PADD 2023 Y 2024",IF(I9<>"","SOLO 2023",IF(J9<>"","SOLO 2024","NO PARTICIPÓ"))) -> SOLO 2024 | L9: 50854 Patapallpa Alta
A10: CUSCO - 44 | B10: 50715 | D10: 1 | F10: 1 | I10: 1 | K10: =IF(AND(I10<>"",J10<>""),"PADD 2023 Y 2024",IF(I10<>"","SOLO 2023",IF(J10<>"","SOLO 2024","NO PARTICIPÓ"))) -> SOLO 2023 | L10: 50715 Llachi
A11: CUSCO - 44 | B11: 50765 | D11: 1 | F11: 1 | I11: 1 | K11: =IF(AND(I11<>"",J11<>""),"PADD 2023 Y 2024",IF(I11<>"","SOLO 2023",IF(J11<>"","SOLO 2024","NO PARTICIPÓ"))) -> SOLO 2023 | L11: 50765 Sallicancha
A12: CUSCO - 44 | B12: 50796 | D12: 1 | F12: 1 | I12: 1 | K12: =IF(AND(I12<>"",J12<>""),"PADD 2023 Y 2024",IF(I12<>"","SOLO 2023",IF(J12<>"","SOLO 2024","NO PARTICIPÓ"))) -> SOLO 2023 | L12: 50796 Yanacancha
A13: CUSCO - 44 | B13: 50495 | D13: 1 | F13: 1 | I13: 1 | K13: =IF(AND(I13<>"",J13<>""),"PADD 2023 Y 2024",IF(I13<>"","SOLO 2023",IF(J13<>"","SOLO 2024","NO PARTICIPÓ"))) -> SOLO 2023 | L13: 50495 Ccapana
A14: CUSCO - 44 | B14: 50536 | C14: 1 | E14: 1 | K14: =IF(AND(I14<>"",J14<>""),"PADD 2023 Y 2024",IF(I14<>"","SOLO 2023",IF(J14<>"","SOLO 2024","NO PARTICIPÓ"))) -> NO PARTICIPÓ | L14: 50536 Ccoñamuro
A15: CUSCO - 44 | B15: 50547 | D15: 1 | F15: 1 | I15: 1 | K15: =IF(AND(I15<>"",J15<>""),"PADD 2023 Y 2024",IF(I15<>"","SOLO 2023",IF(J15<>"","SOLO 2024","NO PARTICIPÓ"))) -> SOLO 2023 | L15: 50547 Accocunca
A16: CUSCO - 44 | B16: 50553 | D16: 1 | F16: 1 | I16: 1 | K16: =IF(AND(I16<>"",J16<>""),"PADD 2023 Y 2024",IF(I16<>"","SOLO 2023",IF(J16<>"","SOLO 2024","NO PARTICIPÓ"))) -> SOLO 2023 | L16: 50553 Marampaqui
A17: CUSCO - 44 | B17: 50912 | C17: 1 | E17: 1 | K17: =IF(AND(I17<>"",J17<>""),"PADD 2023 Y 2024",IF(I17<>"","SOLO 2023",IF(J17<>"","SOLO 2024","NO PARTICIPÓ"))) -> NO PARTICIPÓ | L17: 50912 Cuyuni
A18: CUSCO - 44 | B18: 50977 | D18: 1 | F18: 1 | I18: 1 | K18: =IF(AND(I18<>"",J18<>""),"PADD 2023 Y 2024",IF(I18<>"","SOLO 2023",IF(J18<>"","SOLO 2024","NO PARTICIPÓ"))) -> SOLO 2023 | L18: 50977 Andamayo
A19: CUSCO - 44 | B19: 501432 PAPA FRANCISCO I | C19: 1 | D19: 1 | E19: 1 | F19: 1 | I19: 1 | J19: 1 | K19: =IF(AND(I19<>"",J19<>""),"PADD 2023 Y 2024",IF(I19<>"","SOLO 2023",IF(J19<>"","SOLO 2024","NO PARTICIPÓ"))) -> PADD 2023 Y 2024 | L19: 501432 PAPA FRANCISCO I - Kumuncancha
A20: CUSCO - 44 | B20: ALMIRANTE MIGUEL GRAU SEMINARIO | C20: 1 | E20: 1 | K20: =IF(AND(I20<>"",J20<>""),"PADD 2023 Y 2024",IF(I20<>"","SOLO 2023",IF(J20<>"","SOLO 2024","NO PARTICIPÓ"))) -> NO PARTICIPÓ | L20: ALMIRANTE MIGUEL GRAU SEMINARIO
A21: IQUITOS - 47 | B21: #NUM! | C21: 1 | D21: 1 | E21: 1 | F21: 1 | G21: 1 | H21: 1 | I21: 1 | J21: 1 | K21: =IF(AND(I21<>"",J21<>""),"PADD 2023 Y 2024",IF(I21<>"","SOLO 2023",IF(J21<>"","SOLO 2024","NO PARTICIPÓ"))) -> PADD 2023 Y 2024 | L21: El Milagro
A22: IQUITOS - 47 | B22: 601448 | C22: 1 | D22: 1 | E22: 1 | F22: 1 | G22: 1 | H22: 1 | I22: 1 | J22: 1 | K22: =IF(AND(I22<>"",J22<>""),"PADD 2023 Y 2024",IF(I22<>"","SOLO 2023",IF(J22<>"","SOLO 2024","NO PARTICIPÓ"))) -> PADD 2023 Y 2024 | L22: 601448
A23: IQUITOS - 47 | B23: 601614 | D23: 1 | F23: 1 | H23: 1 | I23: 1 | J23: 1 | K23: =IF(AND(I23<>"",J23<>""),"PADD 2023 Y 2024",IF(I23<>"","SOLO 2023",IF(J23<>"","SOLO 2024","NO PARTICIPÓ"))) -> PADD 2023 Y 2024 | L23: 601614
A24: IQUITOS - 47 | B24: 601514 | D24: 1 | F24: 1 | H24: 1 | I24: 1 | K24: =IF(AND(I24<>"",J24<>""),"PADD 2023 Y 2024",IF(I24<>"","SOLO 2023",IF(J24<>"","SOLO 2024","NO PARTICIPÓ"))) -> SOLO 2023 | L24: 601514
A25: IQUITOS - 47 | B25: 601331 | C25: 1 | D25: 1 | E25: 1 | F25: 1 | G25: 1 | H25: 1 | I25: 1 | K25: =IF(AND(I25<>"",J25<>""),"PADD 2023 Y 2024",IF(I25<>"","SOLO 2023",IF(J25<>"","SOLO 2024","NO PARTICIPÓ"))) -> SOLO 2023 | L25: 601331
A26: IQUITOS - 47 | B26: 6010230 BARBARA D'ACHILLE | C26: 1 | D26: 1 | E26: 1 | F26: 1 | G26: 1 | H26: 1 | I26: 1 | J26: 1 | K26: =IF(AND(I26<>"",J26<>""),"PADD 2023 Y 2024",IF(I26<>"","SOLO 2023",IF(J26<>"","SOLO 2024","NO PARTICIPÓ"))) -> PADD 2023 Y 2024 | L26: 6010230 BARBARA D'ACHILLE
A27: IQUITOS - 47 | B27: 60133 | C27: 1 | D27: 1 | E27: 1 | F27: 1 | G27: 1 | H27: 1 | I27: 1 | J27: 1 | K27: =IF(AND(I27<>"",J27<>""),"PADD 2023 Y 2024",IF(I27<>"","SOLO 2023",IF(J27<>"","SOLO 2024","NO PARTICIPÓ"))) -> PADD 2023 Y 2024 | L27: 60133
A28: IQUITOS - 47 | B28: 60136 | J28: 1 | K28: =IF(AND(I28<>"",J28<>""),"PADD 2023 Y 2024",IF(I28<>"","SOLO 2023",IF(J28<>"","SOLO 2024","NO PARTICIPÓ"))) -> SOLO 2024 | L28: 60136
A29: IQUITOS - 47 | B29: 60181 | J29: 1 | K29: =IF(AND(I29<>"",J29<>""),"PADD 2023 Y 2024",IF(I29<>"","SOLO 2023",IF(J29<>"","SOLO 2024","NO PARTICIPÓ"))) -> SOLO 2024 | L29: 60181
A30: IQUITOS - 47 | B30: 601330 | J30: 1 | K30: =IF(AND(I30<>"",J30<>""),"PADD 2023 Y 2024",IF(I30<>"","SOLO 2023",IF(J30<>"","SOLO 2024","NO PARTICIPÓ"))) -> SOLO 2024 | L30: 601330
A31: IQUITOS - 47 | B31: 601391 | J31: 1 | K31: =IF(AND(I31<>"",J31<>""),"PADD 2023 Y 2024",IF(I31<>"","SOLO 2023",IF(J31<>"","SOLO 2024","NO PARTICIPÓ"))) -> SOLO 2024 | L31: 601391
A32: IQUITOS - 47 | B32: 601444 | J32: 1 | K32: =IF(AND(I32<>"",J32<>""),"PADD 2023 Y 2024",IF(I32<>"","SOLO 2023",IF(J32<>"","SOLO 2024","NO PARTICIPÓ"))) -> SOLO 2024 | L32: 601444
A33: IQUITOS - 47 | B33: 601511 | J33: 1 | K33: =IF(AND(I33<>"",J33<>""),"PADD 2023 Y 2024",IF(I33<>"","SOLO 2023",IF(J33<>"","SOLO 2024","NO PARTICIPÓ"))) -> SOLO 2024 | L33: 601511
A34: IQUITOS - 47 | B34: 601563 | J34: 1 | K34: =IF(AND(I34<>"",J34<>""),"PADD 2023 Y 2024",IF(I34<>"","SOLO 2023",IF(J34<>"","SOLO 2024","NO PARTICIPÓ"))) -> SOLO 2024 | L34: 601563
A35: IQUITOS - 47 | B35: 601570 | J35: 1 | K35: =IF(AND(I35<>"",J35<>""),"PADD 2023 Y 2024",IF(I35<>"","SOLO 2023",IF(J35<>"","SOLO 2024","NO PARTICIPÓ"))) -> SOLO 2024 | L35: 601570
A36: IQUITOS - 47 | B36: 601571 | J36: 1 | K36: =IF(AND(I36<>"",J36<>""),"PADD 2023 Y 2024",IF(I36<>"","SOLO 2023",IF(J36<>"","SOLO 2024","NO PARTICIPÓ"))) -> SOLO 2024 | L36: 601571
A37: IQUITOS - 47 | B37: 601580 | J37: 1 | K37: =IF(AND(I37<>"",J37<>""),"PADD 2023 Y 2024",IF(I37<>"","SOLO 2023",IF(J37<>"","SOLO 2024","NO PARTICIPÓ"))) -> SOLO 2024 | L37: 601580
A38: IQUITOS - 47 | B38: 601678 | J38: 1 | K38: =IF(AND(I38<>"",J38<>""),"PADD 2023 Y 2024",IF(I38<>"","SOLO 2023",IF(J38<>"","SOLO 2024","NO PARTICIPÓ"))) -> SOLO 2024 | L38: 601678
A39: IQUITOS - 47 | B39: 6010102 | J39: 1 | K39: =IF(AND(I39<>"",J39<>""),"PADD 2023 Y 2024",IF(I39<>"","SOLO 2023",IF(J39<>"","SOLO 2024","NO PARTICIPÓ"))) -> SOLO 2024 | L39: 6010102
... A41: IQUITOS - 47 | B41: 6010231 | J41: 1 | K41: =IF(AND(I41<>"",J41<>""),"PADD 2023 Y 2024",IF(I41<>"","SOLO 2023",IF(J41<>"","SOLO 2024","NO PARTICIPÓ"))) -> SOLO 2024 | L41: 6010231
...

Sheet Procesados
C2: Grado | D2: (Varios elementos)
L3: Explicación
C4: COUNTA of R Producción de textos | D4: Año | L4: =callGemini("redacta una oracion explicando esta tabla: "&CONCATENATE(C4:D8)&"se brebe, solo responde sin comentarios adicionales") -> #NAME?
C5: Sexo | D5: 2022 | E5: 2023 | F5: 2024
C6: Femenino | D6: 163 | E6: 456 | F6: 559
C7: Masculino | D7: 192 | E7: 476 | F7: 548
C8: Total general | D8: 355 | E8: 932 | F8: 1107
C11: Sexo | D11: 2024
C12: Femenino | D12: =+GETPIVOTDATA("R Producción de textos",$C$4,"Sexo","Femenino","Año","2024")/GETPIVOTDATA("R Producción de textos",$C$4,"Año","2024") -> 0.50496838
C13: Masculino | D13: =+GETPIVOTDATA("R Producción de textos",$C$4,"Sexo","Masculino","Año","2024")/GETPIVOTDATA("R Producción de textos",$C$4,"Año","2024") -> 0.49503162
C14: Suma total | D14: 1
L21: Explicación
L22: =callGemini("redacta una oracion explicando esta tabla: "&CONCATENATE(C22:D30)&"se brebe, solo responde sin comentarios adicionales") -> #NAME?
C23: COUNTA of Año | D23: Año
C24: Grado | D24: 2022 | E24: 2023 | F24: 2024
C25: 2 Primaria | D25: 24 | E25: 253 | F25: 227
C26: 2 Secundaria | D26: 108 | E26: 125 | F26: 236
C27: 4 Primaria | D27: 42 | E27: 235 | F27: 206
C28: 4 Secundaria | D28: 112 | E28: 96 | F28: 219
C29: 6 Primaria | D29: 69 | E29: 223 | F29: 219
C30: Total general | D30: 355 | E30: 932 | F30: 1107
C33: Grado | D33: 2024
C34: 2 Primaria | D34: =F25/$F$30 -> 0.20505872
C35: 2 Secundaria | D35: =F26/$F$30 -> 0.2131888
C36: 4 Primaria | D36: =F27/$F$30 -> 0.18608853
C37: 4 Secundaria | D37: =F28/$F$30 -> 0.19783198
C38: 6 Primaria | D38: =F29/$F$30 -> 0.19783198
C39: Suma total | D39: =F30/$F$30 -> 1
C42: Grado | D42: (Varios elementos)
L43: Explicación
C44: COUNTA of R Producción de textos | D44: Año | L44: =callGemini("redacta una oracion explicando la respuesta de los estudiantes a la pregunta:: "&CONCATENATE(C44:D52)&"se brebe, solo responde sin comentarios adicionales, agrega datos de la tabla en la respuesta.") -> #NAME?
C45: Región | D45: 2022 | E45: 2023 | F45: 2024
C46: 44. Cusco | F46: 41
C47: 47. Loreto | D47: 165 | E47: 311 | F47: 321
C48: 48. Piura | E48: 445 | F48: 319
C49: 54. Ancash | D49: 37 | E49: 41 | F49: 140
C50: 72. Ucayali | D50: 48 | E50: 56 | F50: 100
C51: 79. Huancavelica | D51: 105 | E51: 79 | F51: 186
C52: Total general | D52: 355 | E52: 932 | F52: 1107
C54: Región | D54: 2024
...

Sheet CLASFICACIÓN
A1: COUNTA of R Producción de textos | C1: Año | F1: AS | G1: A | H1: B
A2: Institución Educativa | B2: Grado | C2: 2022 | D2: 2023 | E2: 2024 | F2: CLASIFICACION | G2: ID | H2: PADD
A3: 14045 | B3: 2 Primaria | E3: 2 | F3: =IF(AND(C3<>"",D3<>"",E3<>""),"LOS 3 AÑOS", IF(AND(C3<>"",IF(AND(C3<>"",D3<>"",E3<>""),"SI","NO")<>"SI",E3<>""),"SOLO 2022 Y 2024",IF(AND(AND(C3="",D3=""),E3<>""),"SOLO 2024",IF(AND(AND(D3<>"",E3<>""),C3=""),"2023 Y 2024", IF(AND(AND(D3="",E3=""),C3<>""),"SOLO LINEA BASE", IF(AND(AND(C3="",E3=""),D3<>""),"SOLO 2023","OTROS ESCENARIOS")))))) -> SOLO 2024 | G3: =A3&B3 -> 140452 Primaria | H3: SOLO 2023
B4: 4 Primaria | E4: 2 | F4: =IF(AND(C4<>"",D4<>"",E4<>""),"LOS 3 AÑOS", IF(AND(C4<>"",IF(AND(C4<>"",D4<>"",E4<>""),"SI","NO")<>"SI",E4<>""),"SOLO 2022 Y 2024",IF(AND(AND(C4="",D4=""),E4<>""),"SOLO 2024",IF(AND(AND(D4<>"",E4<>""),C4=""),"2023 Y 2024", IF(AND(AND(D4="",E4=""),C4<>""),"SOLO LINEA BASE", IF(AND(AND(C4="",E4=""),D4<>""),"SOLO 2023","OTROS ESCENARIOS")))))) -> SOLO 2024 | G4: =A4&B4 -> 4 Primaria | H4: SOLO 2023
B5: 6 Primaria | D5: 3 | E5: 1 | F5: =IF(AND(C5<>"",D5<>"",E5<>""),"LOS 3 AÑOS", IF(AND(C5<>"",IF(AND(C5<>"",D5<>"",E5<>""),"SI","NO")<>"SI",E5<>""),"SOLO 2022 Y 2024",IF(AND(AND(C5="",D5=""),E5<>""),"SOLO 2024",IF(AND(AND(D5<>"",E5<>""),C5=""),"2023 Y 2024", IF(AND(AND(D5="",E5=""),C5<>""),"SOLO LINEA BASE", IF(AND(AND(C5="",E5=""),D5<>""),"SOLO 2023","OTROS ESCENARIOS")))))) -> 2023 Y 2024 | G5: =A5&B5 -> 6 Primaria | H5: SOLO 2023
A6: 14141 | B6: 2 Primaria | D6: 2 | E6: 1 | F6: =IF(AND(C6<>"",D6<>"",E6<>""),"LOS 3 AÑOS", IF(AND(C6<>"",IF(AND(C6<>"",D6<>"",E6<>""),"SI","NO")<>"SI",E6<>""),"SOLO 2022 Y 2024",IF(AND(AND(C6="",D6=""),E6<>""),"SOLO 2024",IF(AND(AND(D6<>"",E6<>""),C6=""),"2023 Y 2024", IF(AND(AND(D6="",E6=""),C6<>""),"SOLO LINEA BASE", IF(AND(AND(C6="",E6=""),D6<>""),"SOLO 2023","OTROS ESCENARIOS")))))) -> 2023 Y 2024 | G6: =A6&B6 -> 141412 Primaria | H6: PADD 2023 Y 2024
B7: 4 Primaria | D7: 6 | E7: 1 | F7: =IF(AND(C7<>"",D7<>"",E7<>""),"LOS 3 AÑOS", IF(AND(C7<>"",IF(AND(C7<>"",D7<>"",E7<>""),"SI","NO")<>"SI",E7<>""),"SOLO 2022 Y 2024",IF(AND(AND(C7="",D7=""),E7<>""),"SOLO 2024",IF(AND(AND(D7<>"",E7<>""),C7=""),"2023 Y 2024", IF(AND(AND(D7="",E7=""),C7<>""),"SOLO LINEA BASE", IF(AND(AND(C7="",E7=""),D7<>""),"SOLO 2023","OTROS ESCENARIOS")))))) -> 2023 Y 2024 | G7: =A7&B7 -> 4 Primaria | H7: PADD 2023 Y 2024
B8: 6 Primaria | D8: 5 | E8: 1 | F8: =IF(AND(C8<>"",D8<>"",E8<>""),"LOS 3 AÑOS", IF(AND(C8<>"",IF(AND(C8<>"",D8<>"",E8<>""),"SI","NO")<>"SI",E8<>""),"SOLO 2022 Y 2024",IF(AND(AND(C8="",D8=""),E8<>""),"SOLO 2024",IF(AND(AND(D8<>"",E8<>""),C8=""),"2023 Y 2024", IF(AND(AND(D8="",E8=""),C8<>""),"SOLO LINEA BASE", IF(AND(AND(C8="",E8=""),D8<>""),"SOLO 2023","OTROS ESCENARIOS")))))) -> 2023 Y 2024 | G8: =A8&B8 -> 6 Primaria | H8: PADD 2023 Y 2024
A9: 14144 SANTA ROSA | B9: 2 Primaria | D9: 57 | E9: 25 | F9: =IF(AND(C9<>"",D9<>"",E9<>""),"LOS 3 AÑOS", IF(AND(C9<>"",IF(AND(C9<>"",D9<>"",E9<>""),"SI","NO")<>"SI",E9<>""),"SOLO 2022 Y 2024",IF(AND(AND(C9="",D9=""),E9<>""),"SOLO 2024",IF(AND(AND(D9<>"",E9<>""),C9=""),"2023 Y 2024", IF(AND(AND(D9="",E9=""),C9<>""),"SOLO LINEA BASE", IF(AND(AND(C9="",E9=""),D9<>""),"SOLO 2023","OTROS ESCENARIOS")))))) -> 2023 Y 2024 | G9: =A9&B9 -> 14144 SANTA ROSA2 Primaria | H9: SOLO 2023
B10: 2 Secundaria | E10: 37 | F10: =IF(AND(C10<>"",D10<>"",E10<>""),"LOS 3 AÑOS", IF(AND(C10<>"",IF(AND(C10<>"",D10<>"",E10<>""),"SI","NO")<>"SI",E10<>""),"SOLO 2022 Y 2024",IF(AND(AND(C10="",D10=""),E10<>""),"SOLO 2024",IF(AND(AND(D10<>"",E10<>""),C10=""),"2023 Y 2024", IF(AND(AND(D10="",E10=""),C10<>""),"SOLO LINEA BASE", IF(AND(AND(C10="",E10=""),D10<>""),"SOLO 2023","OTROS ESCENARIOS")))))) -> SOLO 2024 | G10: =A10&B10 -> 2 Secundaria | H10: SOLO 2023
B11: 4 Primaria | D11: 80 | E11: 20 | F11: =IF(AND(C11<>"",D11<>"",E11<>""),"LOS 3 AÑOS", IF(AND(C11<>"",IF(AND(C11<>"",D11<>"",E11<>""),"SI","NO")<>"SI",E11<>""),"SOLO 2022 Y 2024",IF(AND(AND(C11="",D11=""),E11<>""),"SOLO 2024",IF(AND(AND(D11<>"",E11<>""),C11=""),"2023 Y 2024", IF(AND(AND(D11="",E11=""),C11<>""),"SOLO LINEA BASE", IF(AND(AND(C11="",E11=""),D11<>""),"SOLO 2023","OTROS ESCENARIOS")))))) -> 2023 Y 2024 | G11: =A11&B11 -> 4 Primaria | H11: SOLO 2023
B12: 4 Secundaria | E12: 29 | F12: =IF(AND(C12<>"",D12<>"",E12<>""),"LOS 3 AÑOS", IF(AND(C12<>"",IF(AND(C12<>"",D12<>"",E12<>""),"SI","NO")<>"SI",E12<>""),"SOLO 2022 Y 2024",IF(AND(AND(C12="",D12=""),E12<>""),"SOLO 2024",IF(AND(AND(D12<>"",E12<>""),C12=""),"2023 Y 2024", IF(AND(AND(D12="",E12=""),C12<>""),"SOLO LINEA BASE", IF(AND(AND(C12="",E12=""),D12<>""),"SOLO 2023","OTROS ESCENARIOS")))))) -> SOLO 2024 | G12: =A12&B12 -> 4 Secundaria | H12: SOLO 2023
B13: 6 Primaria | D13: 24 | E13: 24 | F13: =IF(AND(C13<>"",D13<>"",E13<>""),"LOS 3 AÑOS", IF(AND(C13<>"",IF(AND(C13<>"",D13<>"",E13<>""),"SI","NO")<>"SI",E13<>""),"SOLO 2022 Y 2024",IF(AND(AND(C13="",D13=""),E13<>""),"SOLO 2024",IF(AND(AND(D13<>"",E13<>""),C13=""),"2023 Y 2024", IF(AND(AND(D13="",E13=""),C13<>""),"SOLO LINEA BASE", IF(AND(AND(C13="",E13=""),D13<>""),"SOLO 2023","OTROS ESCENARIOS")))))) -> 2023 Y 2024 | G13: =A13&B13 -> 6 Primaria | H13: SOLO 2023
A14: 14145 SANTA JULIA BILLIART | B14: 2 Primaria | D14: 14 | E14: 10 | F14: =IF(AND(C14<>"",D14<>"",E14<>""),"LOS 3 AÑOS", IF(AND(C14<>"",IF(AND(C14<>"",D14<>"",E14<>""),"SI","NO")<>"SI",E14<>""),"SOLO 2022 Y 2024",IF(AND(AND(C14="",D14=""),E14<>""),"SOLO 2024",IF(AND(AND(D14<>"",E14<>""),C14=""),"2023 Y 2024", IF(AND(AND(D14="",E14=""),C14<>""),"SOLO LINEA BASE", IF(AND(AND(C14="",E14=""),D14<>""),"SOLO 2023","OTROS ESCENARIOS")))))) -> 2023 Y 2024 | G14: =A14&B14 -> 14145 SANTA JULIA BILLIART2 Primaria | H14: SOLO 2023
B15: 4 Primaria | D15: 28 | E15: 10 | F15: =IF(AND(C15<>"",D15<>"",E15<>""),"LOS 3 AÑOS", IF(AND(C15<>"",IF(AND(C15<>"",D15<>"",E15<>""),"SI","NO")<>"SI",E15<>""),"SOLO 2022 Y 2024",IF(AND(AND(C15="",D15=""),E15<>""),"SOLO 2024",IF(AND(AND(D15<>"",E15<>""),C15=""),"2023 Y 2024", IF(AND(AND(D15="",E15=""),C15<>""),"SOLO LINEA BASE", IF(AND(AND(C15="",E15=""),D15<>""),"SOLO 2023","OTROS ESCENARIOS")))))) -> 2023 Y 2024 | G15: =A15&B15 -> 4 Primaria | H15: SOLO 2023
B16: 6 Primaria | D16: 30 | E16: 10 | F16: =IF(AND(C16<>"",D16<>"",E16<>""),"LOS 3 AÑOS", IF(AND(C16<>"",IF(AND(C16<>"",D16<>"",E16<>""),"SI","NO")<>"SI",E16<>""),"SOLO 2022 Y 2024",IF(AND(AND(C16="",D16=""),E16<>""),"SOLO 2024",IF(AND(AND(D16<>"",E16<>""),C16=""),"2023 Y 2024", IF(AND(AND(D16="",E16=""),C16<>""),"SOLO LINEA BASE", IF(AND(AND(C16="",E16=""),D16<>""),"SOLO 2023","OTROS ESCENARIOS")))))) -> 2023 Y 2024 | G16: =A16&B16 -> 6 Primaria | H16: SOLO 2023
A17: 14894 | B17: 2 Primaria | E17: 1 | F17: =IF(AND(C17<>"",D17<>"",E17<>""),"LOS 3 AÑOS", IF(AND(C17<>"",IF(AND(C17<>"",D17<>"",E17<>""),"SI","NO")<>"SI",E17<>""),"SOLO 2022 Y 2024",IF(AND(AND(C17="",D17=""),E17<>""),"SOLO 2024",IF(AND(AND(D17<>"",E17<>""),C17=""),"2023 Y 2024", IF(AND(AND(D17="",E17=""),C17<>""),"SOLO LINEA BASE", IF(AND(AND(C17="",E17=""),D17<>""),"SOLO 2023","OTROS ESCENARIOS")))))) -> SOLO 2024 | G17: =A17&B17 -> 148942 Primaria | H17: SOLO 2024
B18: 4 Primaria | E18: 1 | F18: =IF(AND(C18<>"",D18<>"",E18<>""),"LOS 3 AÑOS", IF(AND(C18<>"",IF(AND(C18<>"",D18<>"",E18<>""),"SI","NO")<>"SI",E18<>""),"SOLO 2022 Y 2024",IF(AND(AND(C18="",D18=""),E18<>""),"SOLO 2024",IF(AND(AND(D18<>"",E18<>""),C18=""),"2023 Y 2024", IF(AND(AND(D18="",E18=""),C18<>""),"SOLO LINEA BASE", IF(AND(AND(C18="",E18=""),D18<>""),"SOLO 2023","OTROS ESCENARIOS")))))) -> SOLO 2024 | G18: =A18&B18 -> 4 Primaria | H18: SOLO 2024
A19: 14924 DANIEL ALCIDES CARRION | B19: 2 Primaria | D19: 55 | E19: 21 | F19: =IF(AND(C19<>"",D19<>"",E19<>""),"LOS 3 AÑOS", IF(AND(C19<>"",IF(AND(C19<>"",D19<>"",E19<>""),"SI","NO")<>"SI",E19<>""),"SOLO 2022 Y 2024",IF(AND(AND(C19="",D19=""),E19<>""),"SOLO 2024",IF(AND(AND(D19<>"",E19<>""),C19=""),"2023 Y 2024", IF(AND(AND(D19="",E19=""),C19<>""),"SOLO LINEA BASE", IF(AND(AND(C19="",E19=""),D19<>""),"SOLO 2023","OTROS ESCENARIOS")))))) -> 2023 Y 2024 | G19: =A19&B19 -> 14924 DANIEL ALCIDES CARRION2 Primaria | H19: PADD 2023 Y 2024
B20: 4 Primaria | E20: 22 | F20: =IF(AND(C20<>"",D20<>"",E20<>""),"LOS 3 AÑOS", IF(AND(C20<>"",IF(AND(C20<>"",D20<>"",E20<>""),"SI","NO")<>"SI",E20<>""),"SOLO 2022 Y 2024",IF(AND(AND(C20="",D20=""),E20<>""),"SOLO 2024",IF(AND(AND(D20<>"",E20<>""),C20=""),"2023 Y 2024", IF(AND(AND(D20="",E20=""),C20<>""),"SOLO LINEA BASE", IF(AND(AND(C20="",E20=""),D20<>""),"SOLO 2023","OTROS ESCENARIOS")))))) -> SOLO 2024 | G20: =A20&B20 -> 4 Primaria | H20: PADD 2023 Y 2024
B21: 6 Primaria | E21: 24 | F21: =IF(AND(C21<>"",D21<>"",E21<>""),"LOS 3 AÑOS", IF(AND(C21<>"",IF(AND(C21<>"",D21<>"",E21<>""),"SI","NO")<>"SI",E21<>""),"SOLO 2022 Y 2024",IF(AND(AND(C21="",D21=""),E21<>""),"SOLO 2024",IF(AND(AND(D21<>"",E21<>""),C21=""),"2023 Y 2024", IF(AND(AND(D21="",E21=""),C21<>""),"SOLO LINEA BASE", IF(AND(AND(C21="",E21=""),D21<>""),"SOLO 2023","OTROS ESCENARIOS")))))) -> SOLO 2024 | G21: =A21&B21 -> 6 Primaria | H21: PADD 2023 Y 2024
A22: 14975 | B22: 2 Primaria | D22: 9 | E22: 5 | F22: =IF(AND(C22<>"",D22<>"",E22<>""),"LOS 3 AÑOS", IF(AND(C22<>"",IF(AND(C22<>"",D22<>"",E22<>""),"SI","NO")<>"SI",E22<>""),"SOLO 2022 Y 2024",IF(AND(AND(C22="",D22=""),E22<>""),"SOLO 2024",IF(AND(AND(D22<>"",E22<>""),C22=""),"2023 Y 2024", IF(AND(AND(D22="",E22=""),C22<>""),"SOLO LINEA BASE", IF(AND(AND(C22="",E22=""),D22<>""),"SOLO 2023","OTROS ESCENARIOS")))))) -> 2023 Y 2024 | G22: =A22&B22 -> 149752 Primaria | H22: PADD 2023 Y 2024
B23: 4 Primaria | E23: 6 | F23: =IF(AND(C23<>"",D23<>"",E23<>""),"LOS 3 AÑOS", IF(AND(C23<>"",IF(AND(C23<>"",D23<>"",E23<>""),"SI","NO")<>"SI",E23<>""),"SOLO 2022 Y 2024",IF(AND(AND(C23="",D23=""),E23<>""),"SOLO 2024",IF(AND(AND(D23<>"",E23<>""),C23=""),"2023 Y 2024", IF(AND(AND(D23="",E23=""),C23<>""),"SOLO LINEA BASE", IF(AND(AND(C23="",E23=""),D23<>""),"SOLO 2023","OTROS ESCENARIOS")))))) -> SOLO 2024 | G23: =A23&B23 -> 4 Primaria | H23: PADD 2023 Y 2024
B24: 6 Primaria | D24: 23 | E24: 5 | F24: =IF(AND(C24<>"",D24<>"",E24<>""),"LOS 3 AÑOS", IF(AND(C24<>"",IF(AND(C24<>"",D24<>"",E24<>""),"SI","NO")<>"SI",E24<>""),"SOLO 2022 Y 2024",IF(AND(AND(C24="",D24=""),E24<>""),"SOLO 2024",IF(AND(AND(D24<>"",E24<>""),C24=""),"2023 Y 2024", IF(AND(AND(D24="",E24=""),C24<>""),"SOLO LINEA BASE", IF(AND(AND(C24="",E24=""),D24<>""),"SOLO 2023","OTROS ESCENARIOS")))))) -> 2023 Y 2024 | G24: =A24&B24 -> 6 Primaria | H24: PADD 2023 Y 2024
A25: 15219 | B25: 2 Primaria | D25: 1 | E25: 2 | F25: =IF(AND(C25<>"",D25<>"",E25<>""),"LOS 3 AÑOS", IF(AND(C25<>"",IF(AND(C25<>"",D25<>"",E25<>""),"SI","NO")<>"SI",E25<>""),"SOLO 2022 Y 2024",IF(AND(AND(C25="",D25=""),E25<>""),"SOLO 2024",IF(AND(AND(D25<>"",E25<>""),C25=""),"2023 Y 2024", IF(AND(AND(D25="",E25=""),C25<>""),"SOLO LINEA BASE", IF(AND(AND(C25="",E25=""),D25<>""),"SOLO 2023","OTROS ESCENARIOS")))))) -> 2023 Y 2024 | G25: =A25&B25 -> 152192 Primaria | H25: SOLO 2023
B26: 6 Primaria | D26: 1 | E26: 1 | F26: =IF(AND(C26<>"",D26<>"",E26<>""),"LOS 3 AÑOS", IF(AND(C26<>"",IF(AND(C26<>"",D26<>"",E26<>""),"SI","NO")<>"SI",E26<>""),"SOLO 2022 Y 2024",IF(AND(AND(C26="",D26=""),E26<>""),"SOLO 2024",IF(AND(AND(D26<>"",E26<>""),C26=""),"2023 Y 2024", IF(AND(AND(D26="",E26=""),C26<>""),"SOLO LINEA BASE", IF(AND(AND(C26="",E26=""),D26<>""),"SOLO 2023","OTROS ESCENARIOS")))))) -> 2023 Y 2024 | G26: =A26&B26 -> 6 Primaria | H26: SOLO 2023
A27: 15220 | B27: 6 Primaria | D27: 1 | E27: 1 | F27: =IF(AND(C27<>"",D27<>"",E27<>""),"LOS 3 AÑOS", IF(AND(C27<>"",IF(AND(C27<>"",D27<>"",E27<>""),"SI","NO")<>"SI",E27<>""),"SOLO 2022 Y 2024",IF(AND(AND(C27="",D27=""),E27<>""),"SOLO 2024",IF(AND(AND(D27<>"",E27<>""),C27=""),"2023 Y 2024", IF(AND(AND(D27="",E27=""),C27<>""),"SOLO LINEA BASE", IF(AND(AND(C27="",E27=""),D27<>""),"SOLO 2023","OTROS ESCENARIOS")))))) -> 2023 Y 2024 | G27: =A27&B27 -> 152206 Primaria | H27: SOLO 2023
A28: 15304 | B28: 2 Primaria | D28: 4 | E28: 4 | F28: =IF(AND(C28<>"",D28<>"",E28<>""),"LOS 3 AÑOS", IF(AND(C28<>"",IF(AND(C28<>"",D28<>"",E28<>""),"SI","NO")<>"SI",E28<>""),"SOLO 2022 Y 2024",IF(AND(AND(C28="",D28=""),E28<>""),"SOLO 2024",IF(AND(AND(D28<>"",E28<>""),C28=""),"2023 Y 2024", IF(AND(AND(D28="",E28=""),C28<>""),"SOLO LINEA BASE", IF(AND(AND(C28="",E28=""),D28<>""),"SOLO 2023","OTROS ESCENARIOS")))))) -> 2023 Y 2024 | G28: =A28&B28 -> 153042 Primaria | H28: SOLO 2023
B29: 4 Primaria | D29: 7 | E29: 2 | F29: =IF(AND(C29<>"",D29<>"",E29<>""),"LOS 3 AÑOS", IF(AND(C29<>"",IF(AND(C29<>"",D29<>"",E29<>""),"SI","NO")<>"SI",E29<>""),"SOLO 2022 Y 2024",IF(AND(AND(C29="",D29=""),E29<>""),"SOLO 2024",IF(AND(AND(D29<>"",E29<>""),C29=""),"2023 Y 2024", IF(AND(AND(D29="",E29=""),C29<>""),"SOLO LINEA BASE", IF(AND(AND(C29="",E29=""),D29<>""),"SOLO 2023","OTROS ESCENARIOS")))))) -> 2023 Y 2024 | G29: =A29&B29 -> 4 Primaria | H29: SOLO 2023
B30: 6 Primaria | D30: 8 | E30: 3 | F30: =IF(AND(C30<>"",D30<>"",E30<>""),"LOS 3 AÑOS", IF(AND(C30<>"",IF(AND(C30<>"",D30<>"",E30<>""),"SI","NO")<>"SI",E30<>""),"SOLO 2022 Y 2024",IF(AND(AND(C30="",D30=""),E30<>""),"SOLO 2024",IF(AND(AND(D30<>"",E30<>""),C30=""),"2023 Y 2024", IF(AND(AND(D30="",E30=""),C30<>""),"SOLO LINEA BASE", IF(AND(AND(C30="",E30=""),D30<>""),"SOLO 2023","OTROS ESCENARIOS")))))) -> 2023 Y 2024 | G30: =A30&B30 -> 6 Primaria | H30: SOLO 2023
A31: 15374 | B31: 2 Primaria | E31: 7 | F31: =IF(AND(C31<>"",D31<>"",E31<>""),"LOS 3 AÑOS", IF(AND(C31<>"",IF(AND(C31<>"",D31<>"",E31<>""),"SI","NO")<>"SI",E31<>""),"SOLO 2022 Y 2024",IF(AND(AND(C31="",D31=""),E31<>""),"SOLO 2024",IF(AND(AND(D31<>"",E31<>""),C31=""),"2023 Y 2024", IF(AND(AND(D31="",E31=""),C31<>""),"SOLO LINEA BASE", IF(AND(AND(C31="",E31=""),D31<>""),"SOLO 2023","OTROS ESCENARIOS")))))) -> SOLO 2024 | G31: =A31&B31 -> 153742 Primaria | H31: SOLO 2023
A32: 15383 | B32: 2 Primaria | D32: 1 | F32: =IF(AND(C32<>"",D32<>"",E32<>""),"LOS 3 AÑOS", IF(AND(C32<>"",IF(AND(C32<>"",D32<>"",E32<>""),"SI","NO")<>"SI",E32<>""),"SOLO 2022 Y 2024",IF(AND(AND(C32="",D32=""),E32<>""),"SOLO 2024",IF(AND(AND(D32<>"",E32<>""),C32=""),"2023 Y 2024", IF(AND(AND(D32="",E32=""),C32<>""),"SOLO LINEA BASE", IF(AND(AND(C32="",E32=""),D32<>""),"SOLO 2023","OTROS ESCENARIOS")))))) -> SOLO 2023 | G32: =A32&B32 -> 153832 Primaria | H32: PADD 2023 Y 2024
B33: 4 Primaria | D33: 3 | E33: 1 | F33: =IF(AND(C33<>"",D33<>"",E33<>""),"LOS 3 AÑOS", IF(AND(C33<>"",IF(AND(C33<>"",D33<>"",E33<>""),"SI","NO")<>"SI",E33<>""),"SOLO 2022 Y 2024",IF(AND(AND(C33="",D33=""),E33<>""),"SOLO 2024",IF(AND(AND(D33<>"",E33<>""),C33=""),"2023 Y 2024", IF(AND(AND(D33="",E33=""),C33<>""),"SOLO LINEA BASE", IF(AND(AND(C33="",E33=""),D33<>""),"SOLO 2023","OTROS ESCENARIOS")))))) -> 2023 Y 2024 | G33: =A33&B33 -> 4 Primaria | H33: PADD 2023 Y 2024
B34: 6 Primaria | D34: 2 | F34: =IF(AND(C34<>"",D34<>"",E34<>""),"LOS 3 AÑOS", IF(AND(C34<>"",IF(AND(C34<>"",D34<>"",E34<>""),"SI","NO")<>"SI",E34<>""),"SOLO 2022 Y 2024",IF(AND(AND(C34="",D34=""),E34<>""),"SOLO 2024",IF(AND(AND(D34<>"",E34<>""),C34=""),"2023 Y 2024", IF(AND(AND(D34="",E34=""),C34<>""),"SOLO LINEA BASE", IF(AND(AND(C34="",E34=""),D34<>""),"SOLO 2023","OTROS ESCENARIOS")))))) -> SOLO 2023 | G34: =A34&B34 -> 6 Primaria | H34: PADD 2023 Y 2024
