Workbook

Sheet DATA
A1: Estudiante | B1: Región | C1: Nivel | D1: Grado | E1: Institución Educativa | F1: Ambito | G1: Sexo | H1: R Matemática | I1: Año | J1: ANALISIS | K1: PADD-R | L1: ID. IE | M1: ID2
A2: 1 | B2: 47. Loreto | C2: Primaria | D2: 2 Primaria | E2: =IFERROR(__xludf.DUMMYFUNCTION("FILTER(colegios!$B$2:$B5618,colegios!$A$2:$A5618=L2)"),"60136") -> 60136 | F2: Rural | G2: Femenino | H2: Inicio | I2: 2024 | J2: =IFERROR(__xludf.DUMMYFUNCTION("FILTER('CLASFICACIÓN'!$F$3:$F5618,'CLASFICACIÓN'!$G$3:$G5618=M2)"),"SOLO 2024") -> SOLO 2024 | L2: 60136 MORALILLO | M2: =E2&D2 -> 601362 Primaria
A3: 2 | B3: 47. Loreto | C3: Primaria | D3: 4 Primaria | E3: =IFERROR(__xludf.DUMMYFUNCTION("FILTER(colegios!$B$2:$B5618,colegios!$A$2:$A5618=L3)"),"60136") -> 60136 | F3: Rural | G3: Masculino | H3: Inicio | I3: 2024 | J3: =IFERROR(__xludf.DUMMYFUNCTION("FILTER('CLASFICACIÓN'!$F$3:$F5618,'CLASFICACIÓN'!$G$3:$G5618=M3)"),"SOLO 2024") -> SOLO 2024 | L3: 60136 MORALILLO | M3: =E3&D3 -> 601364 Primaria
A4: 3 | B4: 47. Loreto | C4: Primaria | D4: 4 Primaria | E4: =IFERROR(__xludf.DUMMYFUNCTION("FILTER(colegios!$B$2:$B5618,colegios!$A$2:$A5618=L4)"),"60136") -> 60136 | F4: Rural | G4: Femenino | H4: Inicio | I4: 2024 | J4: =IFERROR(__xludf.DUMMYFUNCTION("FILTER('CLASFICACIÓN'!$F$3:$F5618,'CLASFICACIÓN'!$G$3:$G5618=M4)"),"SOLO 2024") -> SOLO 2024 | L4: 60136 MORALILLO | M4: =E4&D4 -> 601364 Primaria
A5: 4 | B5: 47. Loreto | C5: Primaria | D5: 6 Primaria | E5: =IFERROR(__xludf.DUMMYFUNCTION("FILTER(colegios!$B$2:$B5618,colegios!$A$2:$A5618=L5)"),"60136") -> 60136 | F5: Rural | G5: Masculino | H5: Inicio | I5: 2024 | J5: =IFERROR(__xludf.DUMMYFUNCTION("FILTER('CLASFICACIÓN'!$F$3:$F5618,'CLASFICACIÓN'!$G$3:$G5618=M5)"),"SOLO 2024") -> SOLO 2024 | L5: 60146 MORALILLO | M5: =E5&D5 -> 601366 Primaria
A6: 5 | B6: 47. Loreto | C6: Primaria | D6: 6 Primaria | E6: =IFERROR(__xludf.DUMMYFUNCTION("FILTER(colegios!$B$2:$B5618,colegios!$A$2:$A5618=L6)"),"60136") -> 60136 | F6: Rural | G6: Femenino | H6: Inicio | I6: 2024 | J6: =IFERROR(__xludf.DUMMYFUNCTION("FILTER('CLASFICACIÓN'!$F$3:$F5618,'CLASFICACIÓN'!$G$3:$G5618=M6)"),"SOLO 2024") -> SOLO 2024 | L6: 60136 MORALILLO | M6: =E6&D6 -> 601366 Primaria
A7: 6 | B7: 47. Loreto | C7: Primaria | D7: 2 Primaria | E7: =IFERROR(__xludf.DUMMYFUNCTION("FILTER(colegios!$B$2:$B5618,colegios!$A$2:$A5618=L7)"),"6010102") -> 6010102 | F7: Rural | G7: Masculino | H7: Proceso | I7: 2024 | J7: =IFERROR(__xludf.DUMMYFUNCTION("FILTER('CLASFICACIÓN'!$F$3:$F5618,'CLASFICACIÓN'!$G$3:$G5618=M7)"),"SOLO 2024") -> SOLO 2024 | L7: 6010102 VILLA BUEN PASTOR | M7: =E7&D7 -> 60101022 Primaria
A8: 7 | B8: 47. Loreto | C8: Primaria | D8: 2 Primaria | E8: =IFERROR(__xludf.DUMMYFUNCTION("FILTER(colegios!$B$2:$B5618,colegios!$A$2:$A5618=L8)"),"6010102") -> 6010102 | F8: Rural | G8: Masculino | H8: Inicio | I8: 2024 | J8: =IFERROR(__xludf.DUMMYFUNCTION("FILTER('CLASFICACIÓN'!$F$3:$F5618,'CLASFICACIÓN'!$G$3:$G5618=M8)"),"SOLO 2024") -> SOLO 2024 | L8: 6010102 VILLA BUEN PASTOR | M8: =E8&D8 -> 60101022 Primaria
A9: 8 | B9: 47. Loreto | C9: Primaria | D9: 2 Primaria | E9: =IFERROR(__xludf.DUMMYFUNCTION("FILTER(colegios!$B$2:$B5618,colegios!$A$2:$A5618=L9)"),"6010102") -> 6010102 | F9: Rural | G9: Masculino | H9: Inicio | I9: 2024 | J9: =IFERROR(__xludf.DUMMYFUNCTION("FILTER('CLASFICACIÓN'!$F$3:$F5618,'CLASFICACIÓN'!$G$3:$G5618=M9)"),"SOLO 2024") -> SOLO 2024 | L9: 6010102 VILLA BUEN PASTOR | M9: =E9&D9 -> 60101022 Primaria
A10: 9 | B10: 47. Loreto | C10: Primaria | D10: 4 Primaria | E10: =IFERROR(__xludf.DUMMYFUNCTION("FILTER(colegios!$B$2:$B5618,colegios!$A$2:$A5618=L10)"),"6010102") -> 6010102 | F10: Rural | G10: Masculino | H10: Proceso | I10: 2024 | J10: =IFERROR(__xludf.DUMMYFUNCTION("FILTER('CLASFICACIÓN'!$F$3:$F5618,'CLASFICACIÓN'!$G$3:$G5618=M10)"),"SOLO 2024") -> SOLO 2024 | L10: 6010102 VILLA BUEN PASTOR | M10: =E10&D10 -> 60101024 Primaria
A11: 10 | B11: 47. Loreto | C11: Primaria | D11: 4 Primaria | E11: =IFERROR(__xludf.DUMMYFUNCTION("FILTER(colegios!$B$2:$B5618,colegios!$A$2:$A5618=L11)"),"6010102") -> 6010102 | F11: Rural | G11: Femenino | H11: Proceso | I11: 2024 | J11: =IFERROR(__xludf.DUMMYFUNCTION("FILTER('CLASFICACIÓN'!$F$3:$F5618,'CLASFICACIÓN'!$G$3:$G5618=M11)"),"SOLO 2024") -> SOLO 2024 | L11: 6010102 VILLA BUEN PASTOR | M11: =E11&D11 -> 60101024 Primaria
A12: 11 | B12: 47. Loreto | C12: Primaria | D12: 4 Primaria | E12: =IFERROR(__xludf.DUMMYFUNCTION("FILTER(colegios!$B$2:$B5618,colegios!$A$2:$A5618=L12)"),"6010102") -> 6010102 | F12: Rural | G12: Femenino | H12: Proceso | I12: 2024 | J12: =IFERROR(__xludf.DUMMYFUNCTION("FILTER('CLASFICACIÓN'!$F$3:$F5618,'CLASFICACIÓN'!$G$3:$G5618=M12)"),"SOLO 2024") -> SOLO 2024 | L12: 6010102 VILLA BUEN PASTOR | M12: =E12&D12 -> 60101024 Primaria
A13: 12 | B13: 47. Loreto | C13: Primaria | D13: 4 Primaria | E13: =IFERROR(__xludf.DUMMYFUNCTION("FILTER(colegios!$B$2:$B5618,colegios!$A$2:$A5618=L13)"),"6010102") -> 6010102 | F13: Rural | G13: Masculino | H13: Proceso | I13: 2024 | J13: =IFERROR(__xludf.DUMMYFUNCTION("FILTER('CLASFICACIÓN'!$F$3:$F5618,'CLASFICACIÓN'!$G$3:$G5618=M13)"),"SOLO 2024") -> SOLO 2024 | L13: 6010102 VILLA BUEN PASTOR | M13: =E13&D13 -> 60101024 Primaria
A14: 13 | B14: 47. Loreto | C14: Primaria | D14: 4 Primaria | E14: =IFERROR(__xludf.DUMMYFUNCTION("FILTER(colegios!$B$2:$B5618,colegios!$A$2:$A5618=L14)"),"6010102") -> 6010102 | F14: Rural | G14: Masculino | H14: Proceso | I14: 2024 | J14: =IFERROR(__xludf.DUMMYFUNCTION("FILTER('CLASFICACIÓN'!$F$3:$F5618,'CLASFICACIÓN'!$G$3:$G5618=M14)"),"SOLO 2024") -> SOLO 2024 | L14: 6010102 VILLA BUEN PASTOR | M14: =E14&D14 -> 60101024 Primaria
A15: 14 | B15: 47. Loreto | C15: Primaria | D15: 6 Primaria | E15: =IFERROR(__xludf.DUMMYFUNCTION("FILTER(colegios!$B$2:$B5618,colegios!$A$2:$A5618=L15)"),"6010102") -> 6010102 | F15: Rural | G15: Masculino | H15: Inicio | I15: 2024 | J15: =IFERROR(__xludf.DUMMYFUNCTION("FILTER('CLASFICACIÓN'!$F$3:$F5618,'CLASFICACIÓN'!$G$3:$G5618=M15)"),"SOLO 2024") -> SOLO 2024 | L15: 6010102 VILLA BUEN PASTOR | M15: =E15&D15 -> 60101026 Primaria
A16: 15 | B16: 47. Loreto | C16: Primaria | D16: 6 Primaria | E16: =IFERROR(__xludf.DUMMYFUNCTION("FILTER(colegios!$B$2:$B5618,colegios!$A$2:$A5618=L16)"),"6010102") -> 6010102 | F16: Rural | G16: Femenino | H16: Proceso | I16: 2024 | J16: =IFERROR(__xludf.DUMMYFUNCTION("FILTER('CLASFICACIÓN'!$F$3:$F5618,'CLASFICACIÓN'!$G$3:$G5618=M16)"),"SOLO 2024") -> SOLO 2024 | L16: 6010102 VILLA BUEN PASTOR | M16: =E16&D16 -> 60101026 Primaria
A17: 16 | B17: 47. Loreto | C17: Primaria | D17: 2 Primaria | E17: =IFERROR(__xludf.DUMMYFUNCTION("FILTER(colegios!$B$2:$B5618,colegios!$A$2:$A5618=L17)"),"601448") -> 601448 | F17: Rural | G17: Femenino | H17: Proceso | I17: 2024 | J17: =IFERROR(__xludf.DUMMYFUNCTION("FILTER('CLASFICACIÓN'!$F$3:$F5618,'CLASFICACIÓN'!$G$3:$G5618=M17)"),"LOS 3 AÑOS") -> LOS 3 AÑOS | L17: 601448 NUEVO MILAGRO | M17: =E17&D17 -> 6014482 Primaria
A18: 17 | B18: 47. Loreto | C18: Primaria | D18: 2 Primaria | E18: =IFERROR(__xludf.DUMMYFUNCTION("FILTER(colegios!$B$2:$B5618,colegios!$A$2:$A5618=L18)"),"601448") -> 601448 | F18: Rural | G18: Masculino | H18: Inicio | I18: 2024 | J18: =IFERROR(__xludf.DUMMYFUNCTION("FILTER('CLASFICACIÓN'!$F$3:$F5618,'CLASFICACIÓN'!$G$3:$G5618=M18)"),"LOS 3 AÑOS") -> LOS 3 AÑOS | L18: 601448 NUEVO MILAGRO | M18: =E18&D18 -> 6014482 Primaria
A19: 18 | B19: 47. Loreto | C19: Primaria | D19: 2 Primaria | E19: =IFERROR(__xludf.DUMMYFUNCTION("FILTER(colegios!$B$2:$B5618,colegios!$A$2:$A5618=L19)"),"601448") -> 601448 | F19: Rural | G19: Masculino | H19: Proceso | I19: 2024 | J19: =IFERROR(__xludf.DUMMYFUNCTION("FILTER('CLASFICACIÓN'!$F$3:$F5618,'CLASFICACIÓN'!$G$3:$G5618=M19)"),"LOS 3 AÑOS") -> LOS 3 AÑOS | L19: 601448 NUEVO MILAGRO | M19: =E19&D19 -> 6014482 Primaria
A20: 19 | B20: 47. Loreto | C20: Primaria | D20: 4 Primaria | E20: =IFERROR(__xludf.DUMMYFUNCTION("FILTER(colegios!$B$2:$B5618,colegios!$A$2:$A5618=L20)"),"601448") -> 601448 | F20: Rural | G20: Masculino | H20: Inicio | I20: 2024 | J20: =IFERROR(__xludf.DUMMYFUNCTION("FILTER('CLASFICACIÓN'!$F$3:$F5618,'CLASFICACIÓN'!$G$3:$G5618=M20)"),"LOS 3 AÑOS") -> LOS 3 AÑOS | L20: 601448 NUEVO MILAGRO | M20: =E20&D20 -> 6014484 Primaria
A21: 20 | B21: 47. Loreto | C21: Primaria | D21: 4 Primaria | E21: =IFERROR(__xludf.DUMMYFUNCTION("FILTER(colegios!$B$2:$B5618,colegios!$A$2:$A5618=L21)"),"601448") -> 601448 | F21: Rural | G21: Femenino | H21: Proceso | I21: 2024 | J21: =IFERROR(__xludf.DUMMYFUNCTION("FILTER('CLASFICACIÓN'!$F$3:$F5618,'CLASFICACIÓN'!$G$3:$G5618=M21)"),"LOS 3 AÑOS") -> LOS 3 AÑOS | L21: 601448 NUEVO MILAGRO | M21: =E21&D21 -> 6014484 Primaria
A22: 21 | B22: 47. Loreto | C22: Primaria | D22: 6 Primaria | E22: =IFERROR(__xludf.DUMMYFUNCTION("FILTER(colegios!$B$2:$B5618,colegios!$A$2:$A5618=L22)"),"601448") -> 601448 | F22: Rural | G22: Masculino | H22: Proceso | I22: 2024 | J22: =IFERROR(__xludf.DUMMYFUNCTION("FILTER('CLASFICACIÓN'!$F$3:$F5618,'CLASFICACIÓN'!$G$3:$G5618=M22)"),"LOS 3 AÑOS") -> LOS 3 AÑOS | L22: 601448 NUEVO MILAGRO | M22: =E22&D22 -> 6014486 Primaria
A23: 22 | B23: 47. Loreto | C23: Primaria | D23: 6 Primaria | E23: =IFERROR(__xludf.DUMMYFUNCTION("FILTER(colegios!$B$2:$B5618,colegios!$A$2:$A5618=L23)"),"601448") -> 601448 | F23: Rural | G23: Femenino | H23: Proceso | I23: 2024 | J23: =IFERROR(__xludf.DUMMYFUNCTION("FILTER('CLASFICACIÓN'!$F$3:$F5618,'CLASFICACIÓN'!$G$3:$G5618=M23)"),"LOS 3 AÑOS") -> LOS 3 AÑOS | L23: 601448 NUEVO MILAGRO | M23: =E23&D23 -> 6014486 Primaria
A24: 23 | B24: 47. Loreto | C24: Secundaria | D24: 2 Secundaria | E24: =IFERROR(__xludf.DUMMYFUNCTION("FILTER(colegios!$B$2:$B5618,colegios!$A$2:$A5618=L24)"),"EL MILAGRO") -> EL MILAGRO | F24: Rural | G24: Masculino | H24: Inicio | I24: 2024 | J24: =IFERROR(__xludf.DUMMYFUNCTION("FILTER('CLASFICACIÓN'!$F$3:$F5618,'CLASFICACIÓN'!$G$3:$G5618=M24)"),"LOS 3 AÑOS") -> LOS 3 AÑOS | L24: EL MILAGRO | M24: =E24&D24 -> EL MILAGRO2 Secundaria
A25: 24 | B25: 47. Loreto | C25: Secundaria | D25: 2 Secundaria | E25: =IFERROR(__xludf.DUMMYFUNCTION("FILTER(colegios!$B$2:$B5618,colegios!$A$2:$A5618=L25)"),"EL MILAGRO") -> EL MILAGRO | F25: Rural | G25: Femenino | H25: Inicio | I25: 2024 | J25: =IFERROR(__xludf.DUMMYFUNCTION("FILTER('CLASFICACIÓN'!$F$3:$F5618,'CLASFICACIÓN'!$G$3:$G5618=M25)"),"LOS 3 AÑOS") -> LOS 3 AÑOS | L25: EL MILAGRO | M25: =E25&D25 -> EL MILAGRO2 Secundaria
A26: 25 | B26: 47. Loreto | C26: Secundaria | D26: 2 Secundaria | E26: =IFERROR(__xludf.DUMMYFUNCTION("FILTER(colegios!$B$2:$B5618,colegios!$A$2:$A5618=L26)"),"EL MILAGRO") -> EL MILAGRO | F26: Rural | G26: Femenino | H26: Inicio | I26: 2024 | J26: =IFERROR(__xludf.DUMMYFUNCTION("FILTER('CLASFICACIÓN'!$F$3:$F5618,'CLASFICACIÓN'!$G$3:$G5618=M26)"),"LOS 3 AÑOS") -> LOS 3 AÑOS | L26: EL MILAGRO | M26: =E26&D26 -> EL MILAGRO2 Secundaria
A27: 26 | B27: 47. Loreto | C27: Secundaria | D27: 2 Secundaria | E27: =IFERROR(__xludf.DUMMYFUNCTION("FILTER(colegios!$B$2:$B5618,colegios!$A$2:$A5618=L27)"),"EL MILAGRO") -> EL MILAGRO | F27: Rural | G27: Femenino | H27: Inicio | I27: 2024 | J27: =IFERROR(__xludf.DUMMYFUNCTION("FILTER('CLASFICACIÓN'!$F$3:$F5618,'CLASFICACIÓN'!$G$3:$G5618=M27)"),"LOS 3 AÑOS") -> LOS 3 AÑOS | L27: EL MILAGRO | M27: =E27&D27 -> EL MILAGRO2 Secundaria
A28: 27 | B28: 47. Loreto | C28: Secundaria | D28: 2 Secundaria | E28: =IFERROR(__xludf.DUMMYFUNCTION("FILTER(colegios!$B$2:$B5618,colegios!$A$2:$A5618=L28)"),"EL MILAGRO") -> EL MILAGRO | F28: Rural | G28: Masculino | H28: Proceso | I28: 2024 | J28: =IFERROR(__xludf.DUMMYFUNCTION("FILTER('CLASFICACIÓN'!$F$3:$F5618,'CLASFICACIÓN'!$G$3:$G5618=M28)"),"LOS 3 AÑOS") -> LOS 3 AÑOS | L28: EL MILAGRO | M28: =E28&D28 -> EL MILAGRO2 Secundaria
A29: 28 | B29: 47. Loreto | C29: Secundaria | D29: 2 Secundaria | E29: =IFERROR(__xludf.DUMMYFUNCTION("FILTER(colegios!$B$2:$B5618,colegios!$A$2:$A5618=L29)"),"EL MILAGRO") -> EL MILAGRO | F29: Rural | G29: Femenino | H29: Inicio | I29: 2024 | J29: =IFERROR(__xludf.DUMMYFUNCTION("FILTER('CLASFICACIÓN'!$F$3:$F5618,'CLASFICACIÓN'!$G$3:$G5618=M29)"),"LOS 3 AÑOS") -> LOS 3 AÑOS | L29: EL MILAGRO | M29: =E29&D29 -> EL MILAGRO2 Secundaria
A30: 29 | B30: 47. Loreto | C30: Secundaria | D30: 2 Secundaria | E30: =IFERROR(__xludf.DUMMYFUNCTION("FILTER(colegios!$B$2:$B5618,colegios!$A$2:$A5618=L30)"),"EL MILAGRO") -> EL MILAGRO | F30: Rural | G30: Masculino | H30: Proceso | I30: 2024 | J30: =IFERROR(__xludf.DUMMYFUNCTION("FILTER('CLASFICACIÓN'!$F$3:$F5618,'CLASFICACIÓN'!$G$3:$G5618=M30)"),"LOS 3 AÑOS") -> LOS 3 AÑOS | L30: EL MILAGRO | M30: =E30&D30 -> EL MILAGRO2 Secundaria
A31: 30 | B31: 47. Loreto | C31: Secundaria | D31: 2 Secundaria | E31: =IFERROR(__xludf.DUMMYFUNCTION("FILTER(colegios!$B$2:$B5618,colegios!$A$2:$A5618=L31)"),"EL MILAGRO") -> EL MILAGRO | F31: Rural | G31: Femenino | H31: Inicio | I31: 2024 | J31: =IFERROR(__xludf.DUMMYFUNCTION("FILTER('CLASFICACIÓN'!$F$3:$F5618,'CLASFICACIÓN'!$G$3:$G5618=M31)"),"LOS 3 AÑOS") -> LOS 3 AÑOS | L31: EL MILAGRO | M31: =E31&D31 -> EL MILAGRO2 Secundaria
A32: 31 | B32: 47. Loreto | C32: Secundaria | D32: 2 Secundaria | E32: =IFERROR(__xludf.DUMMYFUNCTION("FILTER(colegios!$B$2:$B5618,colegios!$A$2:$A5618=L32)"),"EL MILAGRO") -> EL MILAGRO | F32: Rural | G32: Femenino | H32: Inicio | I32: 2024 | J32: =IFERROR(__xludf.DUMMYFUNCTION("FILTER('CLASFICACIÓN'!$F$3:$F5618,'CLASFICACIÓN'!$G$3:$G5618=M32)"),"LOS 3 AÑOS") -> LOS 3 AÑOS | L32: EL MILAGRO | M32: =E32&D32 -> EL MILAGRO2 Secundaria
A33: 32 | B33: 47. Loreto | C33: Secundaria | D33: 2 Secundaria | E33: =IFERROR(__xludf.DUMMYFUNCTION("FILTER(colegios!$B$2:$B5618,colegios!$A$2:$A5618=L33)"),"EL MILAGRO") -> EL MILAGRO | F33: Rural | G33: Femenino | H33: Inicio | I33: 2024 | J33: =IFERROR(__xludf.DUMMYFUNCTION("FILTER('CLASFICACIÓN'!$F$3:$F5618,'CLASFICACIÓN'!$G$3:$G5618=M33)"),"LOS 3 AÑOS") -> LOS 3 AÑOS | L33: EL MILAGRO | M33: =E33&D33 -> EL MILAGRO2 Secundaria
A34: 33 | B34: 47. Loreto | C34: Secundaria | D34: 2 Secundaria | E34: =IFERROR(__xludf.DUMMYFUNCTION("FILTER(colegios!$B$2:$B5618,colegios!$A$2:$A5618=L34)"),"EL MILAGRO") -> EL MILAGRO | F34: Rural | G34: Femenino | H34: Inicio | I34: 2024 | J34: =IFERROR(__xludf.DUMMYFUNCTION("FILTER('CLASFICACIÓN'!$F$3:$F5618,'CLASFICACIÓN'!$G$3:$G5618=M34)"),"LOS 3 AÑOS") -> LOS 3 AÑOS | L34: EL MILAGRO | M34: =E34&D34 -> EL MILAGRO2 Secundaria
A35: 34 | B35: 47. Loreto | C35: Secundaria | D35: 2 Secundaria | E35: =IFERROR(__xludf.DUMMYFUNCTION("FILTER(colegios!$B$2:$B5618,colegios!$A$2:$A5618=L35)"),"EL MILAGRO") -> EL MILAGRO | F35: Rural | G35: Femenino | H35: Inicio | I35: 2024 | J35: =IFERROR(__xludf.DUMMYFUNCTION("FILTER('CLASFICACIÓN'!$F$3:$F5618,'CLASFICACIÓN'!$G$3:$G5618=M35)"),"LOS 3 AÑOS") -> LOS 3 AÑOS | L35: EL MILAGRO | M35: =E35&D35 -> EL MILAGRO2 Secundaria
A36: 35 | B36: 47. Loreto | C36: Secundaria | D36: 2 Secundaria | E36: =IFERROR(__xludf.DUMMYFUNCTION("FILTER(colegios!$B$2:$B5618,colegios!$A$2:$A5618=L36)"),"EL MILAGRO") -> EL MILAGRO | F36: Rural | G36: Femenino | H36: Inicio | I36: 2024 | J36: =IFERROR(__xludf.DUMMYFUNCTION("FILTER('CLASFICACIÓN'!$F$3:$F5618,'CLASFICACIÓN'!$G$3:$G5618=M36)"),"LOS 3 AÑOS") -> LOS 3 AÑOS | L36: EL MILAGRO | M36: =E36&D36 -> EL MILAGRO2 Secundaria
A37: 36 | B37: 47. Loreto | C37: Secundaria | D37: 2 Secundaria | E37: =IFERROR(__xludf.DUMMYFUNCTION("FILTER(colegios!$B$2:$B5618,colegios!$A$2:$A5618=L37)"),"EL MILAGRO") -> EL MILAGRO | F37: Rural | G37: Masculino | H37: Inicio | I37: 2024 | J37: =IFERROR(__xludf.DUMMYFUNCTION("FILTER('CLASFICACIÓN'!$F$3:$F5618,'CLASFICACIÓN'!$G$3:$G5618=M37)"),"LOS 3 AÑOS") -> LOS 3 AÑOS | L37: EL MILAGRO | M37: =E37&D37 -> EL MILAGRO2 Secundaria
A38: 37 | B38: 47. Loreto | C38: Secundaria | D38: 2 Secundaria | E38: =IFERROR(__xludf.DUMMYFUNCTION("FILTER(colegios!$B$2:$B5618,colegios!$A$2:$A5618=L38)"),"EL MILAGRO") -> EL MILAGRO | F38: Rural | G38: Femenino | H38: Inicio | I38: 2024 | J38: =IFERROR(__xludf.DUMMYFUNCTION("FILTER('CLASFICACIÓN'!$F$3:$F5618,'CLASFICACIÓN'!$G$3:$G5618=M38)"),"LOS 3 AÑOS") -> LOS 3 AÑOS | L38: EL MILAGRO | M38: =E38&D38 -> EL MILAGRO2 Secundaria
A39: 38 | B39: 47. Loreto | C39: Secundaria | D39: 2 Secundaria | E39: =IFERROR(__xludf.DUMMYFUNCTION("FILTER(colegios!$B$2:$B5618,colegios!$A$2:$A5618=L39)"),"EL MILAGRO") -> EL MILAGRO | F39: Rural | G39: Femenino | H39: Inicio | I39: 2024 | J39: =IFERROR(__xludf.DUMMYFUNCTION("FILTER('CLASFICACIÓN'!$F$3:$F5618,'CLASFICACIÓN'!$G$3:$G5618=M39)"),"LOS 3 AÑOS") -> LOS 3 AÑOS | L39: EL MILAGRO | M39: =E39&D39 -> EL MILAGRO2 Secundaria
A40: 39 | B40: 47. Loreto | C40: Secundaria | D40: 2 Secundaria | E40: =IFERROR(__xludf.DUMMYFUNCTION("FILTER(colegios!$B$2:$B5618,colegios!$A$2:$A5618=L40)"),"EL MILAGRO") -> EL MILAGRO | F40: Rural | G40: Masculino | H40: Inicio | I40: 2024 | J40: =IFERROR(__xludf.DUMMYFUNCTION("FILTER('CLASFICACIÓN'!$F$3:$F5618,'CLASFICACIÓN'!$G$3:$G5618=M40)"),"LOS 3 AÑOS") -> LOS 3 AÑOS | L40: EL MILAGRO | M40: =E40&D40 -> EL MILAGRO2 Secundaria
...

Sheet colegios
A1: =IFERROR(__xludf.DUMMYFUNCTION("IMPORTRANGE(""https://docs.google.com/spreadsheets/d/1G0lKhjdDNZcuaaQlGltXi5PoiboQrtAFuEFhYlQNIWs/edit?gid=1917248718#gid=1917248718"",""Colegios!A1:D"")"),"Institución Educativa") -> Institución Educativa | B1: =IFERROR(__xludf.DUMMYFUNCTION("""COMPUTED_VALUE"""),"Nombre a reemplazar") -> Nombre a reemplazar | C1: =IFERROR(__xludf.DUMMYFUNCTION("""COMPUTED_VALUE"""),"Región") -> Región | D1: =IFERROR(__xludf.DUMMYFUNCTION("""COMPUTED_VALUE"""),"Año") -> Año
A2: =IFERROR(__xludf.DUMMYFUNCTION("""COMPUTED_VALUE"""),"Accocunca") -> Accocunca | B2: =IFERROR(__xludf.DUMMYFUNCTION("""COMPUTED_VALUE"""),"50547") -> 50547
A3: =IFERROR(__xludf.DUMMYFUNCTION("""COMPUTED_VALUE"""),"Andamayo") -> Andamayo | B3: =IFERROR(__xludf.DUMMYFUNCTION("""COMPUTED_VALUE"""),"50977") -> 50977
A4: =IFERROR(__xludf.DUMMYFUNCTION("""COMPUTED_VALUE"""),"Ccapana") -> Ccapana | B4: =IFERROR(__xludf.DUMMYFUNCTION("""COMPUTED_VALUE"""),"50495") -> 50495
A5: =IFERROR(__xludf.DUMMYFUNCTION("""COMPUTED_VALUE"""),"Cristo Rey") -> Cristo Rey | B5: =IFERROR(__xludf.DUMMYFUNCTION("""COMPUTED_VALUE"""),"501455 CRISTO REY TTIKARIY") -> 501455 CRISTO REY TTIKARIY
A6: =IFERROR(__xludf.DUMMYFUNCTION("""COMPUTED_VALUE"""),"Kumuncancha") -> Kumuncancha | B6: =IFERROR(__xludf.DUMMYFUNCTION("""COMPUTED_VALUE"""),"501432 PAPA FRANCISCO I") -> 501432 PAPA FRANCISCO I
A7: =IFERROR(__xludf.DUMMYFUNCTION("""COMPUTED_VALUE"""),"Llachi") -> Llachi | B7: =IFERROR(__xludf.DUMMYFUNCTION("""COMPUTED_VALUE"""),"50715") -> 50715
A8: =IFERROR(__xludf.DUMMYFUNCTION("""COMPUTED_VALUE"""),"Marampaqui") -> Marampaqui | B8: =IFERROR(__xludf.DUMMYFUNCTION("""COMPUTED_VALUE"""),"50553") -> 50553
A9: =IFERROR(__xludf.DUMMYFUNCTION("""COMPUTED_VALUE"""),"Ocongate") -> Ocongate | B9: =IFERROR(__xludf.DUMMYFUNCTION("""COMPUTED_VALUE"""),"50492 CORAZON DE JESUS") -> 50492 CORAZON DE JESUS
A10: =IFERROR(__xludf.DUMMYFUNCTION("""COMPUTED_VALUE"""),"Pampacancha") -> Pampacancha | B10: =IFERROR(__xludf.DUMMYFUNCTION("""COMPUTED_VALUE"""),"50550") -> 50550
A11: =IFERROR(__xludf.DUMMYFUNCTION("""COMPUTED_VALUE"""),"Sallicancha") -> Sallicancha | B11: =IFERROR(__xludf.DUMMYFUNCTION("""COMPUTED_VALUE"""),"50765") -> 50765
A12: =IFERROR(__xludf.DUMMYFUNCTION("""COMPUTED_VALUE"""),"Yanacancha") -> Yanacancha | B12: =IFERROR(__xludf.DUMMYFUNCTION("""COMPUTED_VALUE"""),"50696 YANACANCHA") -> 50696 YANACANCHA
A13: =IFERROR(__xludf.DUMMYFUNCTION("""COMPUTED_VALUE"""),"50492- CORAZON DE JESUS OCONGATE") -> 50492- CORAZON DE JESUS OCONGATE | B13: =IFERROR(__xludf.DUMMYFUNCTION("""COMPUTED_VALUE"""),"50492 CORAZON DE JESUS") -> 50492 CORAZON DE JESUS
A14: =IFERROR(__xludf.DUMMYFUNCTION("""COMPUTED_VALUE"""),"50495 CCAPANA") -> 50495 CCAPANA | B14: =IFERROR(__xludf.DUMMYFUNCTION("""COMPUTED_VALUE"""),"50495") -> 50495
A15: =IFERROR(__xludf.DUMMYFUNCTION("""COMPUTED_VALUE"""),"50547 Accocunca") -> 50547 Accocunca | B15: =IFERROR(__xludf.DUMMYFUNCTION("""COMPUTED_VALUE"""),"50547") -> 50547
A16: =IFERROR(__xludf.DUMMYFUNCTION("""COMPUTED_VALUE"""),"50550 PAMPACANCHA") -> 50550 PAMPACANCHA | B16: =IFERROR(__xludf.DUMMYFUNCTION("""COMPUTED_VALUE"""),"50550") -> 50550
A17: =IFERROR(__xludf.DUMMYFUNCTION("""COMPUTED_VALUE"""),"50552 ""TÚPAC AMARU II"" - HUACATINCO") -> 50552 "TÚPAC AMARU II" - HUACATINCO | B17: =IFERROR(__xludf.DUMMYFUNCTION("""COMPUTED_VALUE"""),"50552 TUPAC AMARU II") -> 50552 TUPAC AMARU II
A18: =IFERROR(__xludf.DUMMYFUNCTION("""COMPUTED_VALUE"""),"50553 MARAMPAQUI") -> 50553 MARAMPAQUI | B18: =IFERROR(__xludf.DUMMYFUNCTION("""COMPUTED_VALUE"""),"50553") -> 50553
A19: =IFERROR(__xludf.DUMMYFUNCTION("""COMPUTED_VALUE"""),"50558 PARCCOCALLA") -> 50558 PARCCOCALLA | B19: =IFERROR(__xludf.DUMMYFUNCTION("""COMPUTED_VALUE"""),"50558") -> 50558
A20: =IFERROR(__xludf.DUMMYFUNCTION("""COMPUTED_VALUE"""),"50715 - Llachi") -> 50715 - Llachi | B20: =IFERROR(__xludf.DUMMYFUNCTION("""COMPUTED_VALUE"""),"50715") -> 50715
A21: =IFERROR(__xludf.DUMMYFUNCTION("""COMPUTED_VALUE"""),"50719- VIRGEN DEL CARMEN TINKE") -> 50719- VIRGEN DEL CARMEN TINKE | B21: =IFERROR(__xludf.DUMMYFUNCTION("""COMPUTED_VALUE"""),"50719 VIRGEN DEL CARMEN") -> 50719 VIRGEN DEL CARMEN
A22: =IFERROR(__xludf.DUMMYFUNCTION("""COMPUTED_VALUE"""),"50765 - SALLICANCHA") -> 50765 - SALLICANCHA | B22: =IFERROR(__xludf.DUMMYFUNCTION("""COMPUTED_VALUE"""),"50765") -> 50765
A23: =IFERROR(__xludf.DUMMYFUNCTION("""COMPUTED_VALUE"""),"50696 YANACANCHA") -> 50696 YANACANCHA | B23: =IFERROR(__xludf.DUMMYFUNCTION("""COMPUTED_VALUE"""),"50696 YANACANCHA") -> 50696 YANACANCHA
A24: =IFERROR(__xludf.DUMMYFUNCTION("""COMPUTED_VALUE"""),"50854 de PATAPALLAPA ALTA") -> 50854 de PATAPALLAPA ALTA | B24: =IFERROR(__xludf.DUMMYFUNCTION("""COMPUTED_VALUE"""),"50854") -> 50854
A25: =IFERROR(__xludf.DUMMYFUNCTION("""COMPUTED_VALUE"""),"50977 Andamayo") -> 50977 Andamayo | B25: =IFERROR(__xludf.DUMMYFUNCTION("""COMPUTED_VALUE"""),"50977") -> 50977
A26: =IFERROR(__xludf.DUMMYFUNCTION("""COMPUTED_VALUE"""),"501344 - CCASAPATA") -> 501344 - CCASAPATA | B26: =IFERROR(__xludf.DUMMYFUNCTION("""COMPUTED_VALUE"""),"501344") -> 501344
A27: =IFERROR(__xludf.DUMMYFUNCTION("""COMPUTED_VALUE"""),"501344- CCASAPATA") -> 501344- CCASAPATA | B27: =IFERROR(__xludf.DUMMYFUNCTION("""COMPUTED_VALUE"""),"501344") -> 501344
A28: =IFERROR(__xludf.DUMMYFUNCTION("""COMPUTED_VALUE"""),"501432 - Kumuncancha") -> 501432 - Kumuncancha | B28: =IFERROR(__xludf.DUMMYFUNCTION("""COMPUTED_VALUE"""),"501432 PAPA FRANCISCO I") -> 501432 PAPA FRANCISCO I
A29: =IFERROR(__xludf.DUMMYFUNCTION("""COMPUTED_VALUE"""),"501455 - CRISTO REY TIKARIY") -> 501455 - CRISTO REY TIKARIY | B29: =IFERROR(__xludf.DUMMYFUNCTION("""COMPUTED_VALUE"""),"501455 CRISTO REY TTIKARIY") -> 501455 CRISTO REY TTIKARIY
A30: =IFERROR(__xludf.DUMMYFUNCTION("""COMPUTED_VALUE"""),"Papa Francisco I") -> Papa Francisco I | B30: =IFERROR(__xludf.DUMMYFUNCTION("""COMPUTED_VALUE"""),"501432 PAPA FRANCISCO I") -> 501432 PAPA FRANCISCO I
A31: =IFERROR(__xludf.DUMMYFUNCTION("""COMPUTED_VALUE"""),"601448") -> 601448 | B31: =IFERROR(__xludf.DUMMYFUNCTION("""COMPUTED_VALUE"""),"601448") -> 601448
A32: =IFERROR(__xludf.DUMMYFUNCTION("""COMPUTED_VALUE"""),"601148") -> 601148 | B32: =IFERROR(__xludf.DUMMYFUNCTION("""COMPUTED_VALUE"""),"601448") -> 601448
A33: =IFERROR(__xludf.DUMMYFUNCTION("""COMPUTED_VALUE"""),"601614") -> 601614 | B33: =IFERROR(__xludf.DUMMYFUNCTION("""COMPUTED_VALUE"""),"601614") -> 601614
A34: =IFERROR(__xludf.DUMMYFUNCTION("""COMPUTED_VALUE"""),"EL MILAGRO") -> EL MILAGRO | B34: =IFERROR(__xludf.DUMMYFUNCTION("""COMPUTED_VALUE"""),"EL MILAGRO") -> EL MILAGRO
A35: =IFERROR(__xludf.DUMMYFUNCTION("""COMPUTED_VALUE"""),"EL MILAGRO ") -> EL MILAGRO | B35: =IFERROR(__xludf.DUMMYFUNCTION("""COMPUTED_VALUE"""),"EL MILAGRO") -> EL MILAGRO
A36: =IFERROR(__xludf.DUMMYFUNCTION("""COMPUTED_VALUE"""),"601514") -> 601514 | B36: =IFERROR(__xludf.DUMMYFUNCTION("""COMPUTED_VALUE"""),"601514") -> 601514
A37: =IFERROR(__xludf.DUMMYFUNCTION("""COMPUTED_VALUE"""),"601331") -> 601331 | B37: =IFERROR(__xludf.DUMMYFUNCTION("""COMPUTED_VALUE"""),"601331") -> 601331
A38: =IFERROR(__xludf.DUMMYFUNCTION("""COMPUTED_VALUE"""),"6010230") -> 6010230 | B38: =IFERROR(__xludf.DUMMYFUNCTION("""COMPUTED_VALUE"""),"6010230 BARBARA D'ACHILLE") -> 6010230 BARBARA D'ACHILLE
A39: =IFERROR(__xludf.DUMMYFUNCTION("""COMPUTED_VALUE"""),"60133") -> 60133 | B39: =IFERROR(__xludf.DUMMYFUNCTION("""COMPUTED_VALUE"""),"60133") -> 60133
A40: =IFERROR(__xludf.DUMMYFUNCTION("""COMPUTED_VALUE"""),"60136 MORALILLO") -> 60136 MORALILLO | B40: =IFERROR(__xludf.DUMMYFUNCTION("""COMPUTED_VALUE"""),"60136") -> 60136
...

Sheet PADD-R
A1: RER | B1: IIEE | C1: LÍNEA BASE 2022 | D1: LÍNEA BASE 2023 | E1: LÍNEA BASE 2022 | F1: LÍNEA BASE 2023 | G1: LÍNEA BASE 2022 | H1: LÍNEA BASE 2023 | I1: PADD 2023 | J1: PADD 2024 | K1: PADD | L1: ID IIEE
A2: CUSCO - 44 | B2: {=DGET(colegios!$A$1:$B965,colegios!$B$1,{colegios!$A$1;L2})} -> 501344 | J2: 1 | K2: =IF(AND(I2<>"",J2<>""),"PADD 2023 Y 2024",IF(I2<>"","SOLO 2023",IF(J2<>"","SOLO 2024","NO PARTICIPÓ"))) -> SOLO 2024 | L2: 501344 Ccasapata
A3: CUSCO - 44 | B3: {=DGET(colegios!$A$1:$B965,colegios!$B$1,{colegios!$A$1;L3})} -> 501455 CRISTO REY TTIKARIY | D3: 1 | F3: 1 | I3: 1 | J3: 1 | K3: =IF(AND(I3<>"",J3<>""),"PADD 2023 Y 2024",IF(I3<>"","SOLO 2023",IF(J3<>"","SOLO 2024","NO PARTICIPÓ"))) -> PADD 2023 Y 2024 | L3: 501455 Cristo Rey Ttikariy- Pacchanta Baja
A4: CUSCO - 44 | B4: {=DGET(colegios!$A$1:$B965,colegios!$B$1,{colegios!$A$1;L4})} -> 50492 CORAZON DE JESUS | C4: 1 | D4: 1 | E4: 1 | F4: 1 | I4: 1 | J4: 1 | K4: =IF(AND(I4<>"",J4<>""),"PADD 2023 Y 2024",IF(I4<>"","SOLO 2023",IF(J4<>"","SOLO 2024","NO PARTICIPÓ"))) -> PADD 2023 Y 2024 | L4: 50492 "Corazón de Jesús" Ocongate
A5: CUSCO - 44 | B5: {=DGET(colegios!$A$1:$B965,colegios!$B$1,{colegios!$A$1;L5})} -> 50550 | C5: 1 | D5: 1 | E5: 1 | F5: 1 | I5: 1 | J5: 1 | K5: =IF(AND(I5<>"",J5<>""),"PADD 2023 Y 2024",IF(I5<>"","SOLO 2023",IF(J5<>"","SOLO 2024","NO PARTICIPÓ"))) -> PADD 2023 Y 2024 | L5: 50550 Pampacancha
A6: CUSCO - 44 | B6: {=DGET(colegios!$A$1:$B965,colegios!$B$1,{colegios!$A$1;L6})} -> 50552 TUPAC AMARU II | J6: 1 | K6: =IF(AND(I6<>"",J6<>""),"PADD 2023 Y 2024",IF(I6<>"","SOLO 2023",IF(J6<>"","SOLO 2024","NO PARTICIPÓ"))) -> SOLO 2024 | L6: 50552 Tupac Amaru II - Huacatinco
A7: CUSCO - 44 | B7: {=DGET(colegios!$A$1:$B965,colegios!$B$1,{colegios!$A$1;L7})} -> 50558 | C7: 1 | E7: 1 | J7: 1 | K7: =IF(AND(I7<>"",J7<>""),"PADD 2023 Y 2024",IF(I7<>"","SOLO 2023",IF(J7<>"","SOLO 2024","NO PARTICIPÓ"))) -> SOLO 2024 | L7: 50558 Parccocalla
A8: CUSCO - 44 | B8: {=DGET(colegios!$A$1:$B965,colegios!$B$1,{colegios!$A$1;L8})} -> 50719 VIRGEN DEL CARMEN | C8: 1 | E8: 1 | J8: 1 | K8: =IF(AND(I8<>"",J8<>""),"PADD 2023 Y 2024",IF(I8<>"","SOLO 2023",IF(J8<>"","SOLO 2024","NO PARTICIPÓ"))) -> SOLO 2024 | L8: 50719 Virgen del Carmen de Tinke
A9: CUSCO - 44 | B9: {=DGET(colegios!$A$1:$B965,colegios!$B$1,{colegios!$A$1;L9})} -> 50854 | C9: 1 | E9: 1 | J9: 1 | K9: =IF(AND(I9<>"",J9<>""),"PADD 2023 Y 2024",IF(I9<>"","SOLO 2023",IF(J9<>"","SOLO 2024","NO PARTICIPÓ"))) -> SOLO 2024 | L9: 50854 Patapallpa Alta
A10: CUSCO - 44 | B10: {=DGET(colegios!$A$1:$B965,colegios!$B$1,{colegios!$A$1;L10})} -> 50715 | D10: 1 | F10: 1 | I10: 1 | K10: =IF(AND(I10<>"",J10<>""),"PADD 2023 Y 2024",IF(I10<>"","SOLO 2023",IF(J10<>"","SOLO 2024","NO PARTICIPÓ"))) -> SOLO 2023 | L10: 50715 Llachi
A11: CUSCO - 44 | B11: {=DGET(colegios!$A$1:$B965,colegios!$B$1,{colegios!$A$1;L11})} -> 50765 | D11: 1 | F11: 1 | I11: 1 | K11: =IF(AND(I11<>"",J11<>""),"PADD 2023 Y 2024",IF(I11<>"","SOLO 2023",IF(J11<>"","SOLO 2024","NO PARTICIPÓ"))) -> SOLO 2023 | L11: 50765 Sallicancha
A12: CUSCO - 44 | B12: {=DGET(colegios!$A$1:$B965,colegios!$B$1,{colegios!$A$1;L12})} -> 50796 | D12: 1 | F12: 1 | I12: 1 | K12: =IF(AND(I12<>"",J12<>""),"PADD 2023 Y 2024",IF(I12<>"","SOLO 2023",IF(J12<>"","SOLO 2024","NO PARTICIPÓ"))) -> SOLO 2023 | L12: 50796 Yanacancha
A13: CUSCO - 44 | B13: {=DGET(colegios!$A$1:$B965,colegios!$B$1,{colegios!$A$1;L13})} -> 50495 | D13: 1 | F13: 1 | I13: 1 | K13: =IF(AND(I13<>"",J13<>""),"PADD 2023 Y 2024",IF(I13<>"","SOLO 2023",IF(J13<>"","SOLO 2024","NO PARTICIPÓ"))) -> SOLO 2023 | L13: 50495 Ccapana
A14: CUSCO - 44 | B14: {=DGET(colegios!$A$1:$B965,colegios!$B$1,{colegios!$A$1;L14})} -> 50536 | C14: 1 | E14: 1 | K14: =IF(AND(I14<>"",J14<>""),"PADD 2023 Y 2024",IF(I14<>"","SOLO 2023",IF(J14<>"","SOLO 2024","NO PARTICIPÓ"))) -> NO PARTICIPÓ | L14: 50536 Ccoñamuro
A15: CUSCO - 44 | B15: {=DGET(colegios!$A$1:$B965,colegios!$B$1,{colegios!$A$1;L15})} -> 50547 | D15: 1 | F15: 1 | I15: 1 | K15: =IF(AND(I15<>"",J15<>""),"PADD 2023 Y 2024",IF(I15<>"","SOLO 2023",IF(J15<>"","SOLO 2024","NO PARTICIPÓ"))) -> SOLO 2023 | L15: 50547 Accocunca
A16: CUSCO - 44 | B16: {=DGET(colegios!$A$1:$B965,colegios!$B$1,{colegios!$A$1;L16})} -> 50553 | D16: 1 | F16: 1 | I16: 1 | K16: =IF(AND(I16<>"",J16<>""),"PADD 2023 Y 2024",IF(I16<>"","SOLO 2023",IF(J16<>"","SOLO 2024","NO PARTICIPÓ"))) -> SOLO 2023 | L16: 50553 Marampaqui
A17: CUSCO - 44 | B17: {=DGET(colegios!$A$1:$B965,colegios!$B$1,{colegios!$A$1;L17})} -> 50912 | C17: 1 | E17: 1 | K17: =IF(AND(I17<>"",J17<>""),"PADD 2023 Y 2024",IF(I17<>"","SOLO 2023",IF(J17<>"","SOLO 2024","NO PARTICIPÓ"))) -> NO PARTICIPÓ | L17: 50912 Cuyuni
A18: CUSCO - 44 | B18: {=DGET(colegios!$A$1:$B965,colegios!$B$1,{colegios!$A$1;L18})} -> 50977 | D18: 1 | F18: 1 | I18: 1 | K18: =IF(AND(I18<>"",J18<>""),"PADD 2023 Y 2024",IF(I18<>"","SOLO 2023",IF(J18<>"","SOLO 2024","NO PARTICIPÓ"))) -> SOLO 2023 | L18: 50977 Andamayo
A19: CUSCO - 44 | B19: {=DGET(colegios!$A$1:$B965,colegios!$B$1,{colegios!$A$1;L19})} -> 501432 PAPA FRANCISCO I | C19: 1 | D19: 1 | E19: 1 | F19: 1 | I19: 1 | J19: 1 | K19: =IF(AND(I19<>"",J19<>""),"PADD 2023 Y 2024",IF(I19<>"","SOLO 2023",IF(J19<>"","SOLO 2024","NO PARTICIPÓ"))) -> PADD 2023 Y 2024 | L19: 501432 PAPA FRANCISCO I - Kumuncancha
A20: CUSCO - 44 | B20: {=DGET(colegios!$A$1:$B965,colegios!$B$1,{colegios!$A$1;L20})} -> ALMIRANTE MIGUEL GRAU SEMINARIO | C20: 1 | E20: 1 | K20: =IF(AND(I20<>"",J20<>""),"PADD 2023 Y 2024",IF(I20<>"","SOLO 2023",IF(J20<>"","SOLO 2024","NO PARTICIPÓ"))) -> NO PARTICIPÓ | L20: ALMIRANTE MIGUEL GRAU SEMINARIO
A21: IQUITOS - 47 | B21: {=DGET(colegios!$A$1:$B965,colegios!$B$1,{colegios!$A$1;L21})} -> #NUM! | C21: 1 | D21: 1 | E21: 1 | F21: 1 | G21: 1 | H21: 1 | I21: 1 | J21: 1 | K21: =IF(AND(I21<>"",J21<>""),"PADD 2023 Y 2024",IF(I21<>"","SOLO 2023",IF(J21<>"","SOLO 2024","NO PARTICIPÓ"))) -> PADD 2023 Y 2024 | L21: El Milagro
A22: IQUITOS - 47 | B22: {=DGET(colegios!$A$1:$B965,colegios!$B$1,{colegios!$A$1;L22})} -> 601448 | C22: 1 | D22: 1 | E22: 1 | F22: 1 | G22: 1 | H22: 1 | I22: 1 | J22: 1 | K22: =IF(AND(I22<>"",J22<>""),"PADD 2023 Y 2024",IF(I22<>"","SOLO 2023",IF(J22<>"","SOLO 2024","NO PARTICIPÓ"))) -> PADD 2023 Y 2024 | L22: 601448
A23: IQUITOS - 47 | B23: {=DGET(colegios!$A$1:$B965,colegios!$B$1,{colegios!$A$1;L23})} -> 601614 | D23: 1 | F23: 1 | H23: 1 | I23: 1 | J23: 1 | K23: =IF(AND(I23<>"",J23<>""),"PADD 2023 Y 2024",IF(I23<>"","SOLO 2023",IF(J23<>"","SOLO 2024","NO PARTICIPÓ"))) -> PADD 2023 Y 2024 | L23: 601614
A24: IQUITOS - 47 | B24: {=DGET(colegios!$A$1:$B965,colegios!$B$1,{colegios!$A$1;L24})} -> 601514 | D24: 1 | F24: 1 | H24: 1 | I24: 1 | K24: =IF(AND(I24<>"",J24<>""),"PADD 2023 Y 2024",IF(I24<>"","SOLO 2023",IF(J24<>"","SOLO 2024","NO PARTICIPÓ"))) -> SOLO 2023 | L24: 601514
A25: IQUITOS - 47 | B25: {=DGET(colegios!$A$1:$B965,colegios!$B$1,{colegios!$A$1;L25})} -> 601331 | C25: 1 | D25: 1 | E25: 1 | F25: 1 | G25: 1 | H25: 1 | I25: 1 | K25: =IF(AND(I25<>"",J25<>""),"PADD 2023 Y 2024",IF(I25<>"","SOLO 2023",IF(J25<>"","SOLO 2024","NO PARTICIPÓ"))) -> SOLO 2023 | L25: 601331
A26: IQUITOS - 47 | B26: {=DGET(colegios!$A$1:$B965,colegios!$B$1,{colegios!$A$1;L26})} -> 6010230 BARBARA D'ACHILLE | C26: 1 | D26: 1 | E26: 1 | F26: 1 | G26: 1 | H26: 1 | I26: 1 | J26: 1 | K26: =IF(AND(I26<>"",J26<>""),"PADD 2023 Y 2024",IF(I26<>"","SOLO 2023",IF(J26<>"","SOLO 2024","NO PARTICIPÓ"))) -> PADD 2023 Y 2024 | L26: 6010230 BARBARA D'ACHILLE
A27: IQUITOS - 47 | B27: {=DGET(colegios!$A$1:$B965,colegios!$B$1,{colegios!$A$1;L27})} -> 60133 | C27: 1 | D27: 1 | E27: 1 | F27: 1 | G27: 1 | H27: 1 | I27: 1 | J27: 1 | K27: =IF(AND(I27<>"",J27<>""),"PADD 2023 Y 2024",IF(I27<>"","SOLO 2023",IF(J27<>"","SOLO 2024","NO PARTICIPÓ"))) -> PADD 2023 Y 2024 | L27: 60133
A28: IQUITOS - 47 | B28: {=DGET(colegios!$A$1:$B965,colegios!$B$1,{colegios!$A$1;L28})} -> 60136 | J28: 1 | K28: =IF(AND(I28<>"",J28<>""),"PADD 2023 Y 2024",IF(I28<>"","SOLO 2023",IF(J28<>"","SOLO 2024","NO PARTICIPÓ"))) -> SOLO 2024 | L28: 60136
A29: IQUITOS - 47 | B29: {=DGET(colegios!$A$1:$B965,colegios!$B$1,{colegios!$A$1;L29})} -> 60181 | J29: 1 | K29: =IF(AND(I29<>"",J29<>""),"PADD 2023 Y 2024",IF(I29<>"","SOLO 2023",IF(J29<>"","SOLO 2024","NO PARTICIPÓ"))) -> SOLO 2024 | L29: 60181
A30: IQUITOS - 47 | B30: {=DGET(colegios!$A$1:$B965,colegios!$B$1,{colegios!$A$1;L30})} -> 601330 | J30: 1 | K30: =IF(AND(I30<>"",J30<>""),"PADD 2023 Y 2024",IF(I30<>"","SOLO 2023",IF(J30<>"","SOLO 2024","NO PARTICIPÓ"))) -> SOLO 2024 | L30: 601330
A31: IQUITOS - 47 | B31: {=DGET(colegios!$A$1:$B965,colegios!$B$1,{colegios!$A$1;L31})} -> 601391 | J31: 1 | K31: =IF(AND(I31<>"",J31<>""),"PADD 2023 Y 2024",IF(I31<>"","SOLO 2023",IF(J31<>"","SOLO 2024","NO PARTICIPÓ"))) -> SOLO 2024 | L31: 601391
A32: IQUITOS - 47 | B32: {=DGET(colegios!$A$1:$B965,colegios!$B$1,{colegios!$A$1;L32})} -> 601444 | J32: 1 | K32: =IF(AND(I32<>"",J32<>""),"PADD 2023 Y 2024",IF(I32<>"","SOLO 2023",IF(J32<>"","SOLO 2024","NO PARTICIPÓ"))) -> SOLO 2024 | L32: 601444
A33: IQUITOS - 47 | B33: {=DGET(colegios!$A$1:$B965,colegios!$B$1,{colegios!$A$1;L33})} -> 601511 | J33: 1 | K33: =IF(AND(I33<>"",J33<>""),"PADD 2023 Y 2024",IF(I33<>"","SOLO 2023",IF(J33<>"","SOLO 2024","NO PARTICIPÓ"))) -> SOLO 2024 | L33: 601511
A34: IQUITOS - 47 | B34: {=DGET(colegios!$A$1:$B965,colegios!$B$1,{colegios!$A$1;L34})} -> 601563 | J34: 1 | K34: =IF(AND(I34<>"",J34<>""),"PADD 2023 Y 2024",IF(I34<>"","SOLO 2023",IF(J34<>"","SOLO 2024","NO PARTICIPÓ"))) -> SOLO 2024 | L34: 601563
A35: IQUITOS - 47 | B35: {=DGET(colegios!$A$1:$B965,colegios!$B$1,{colegios!$A$1;L35})} -> 601570 | J35: 1 | K35: =IF(AND(I35<>"",J35<>""),"PADD 2023 Y 2024",IF(I35<>"","SOLO 2023",IF(J35<>"","SOLO 2024","NO PARTICIPÓ"))) -> SOLO 2024 | L35: 601570
A36: IQUITOS - 47 | B36: {=DGET(colegios!$A$1:$B965,colegios!$B$1,{colegios!$A$1;L36})} -> 601571 | J36: 1 | K36: =IF(AND(I36<>"",J36<>""),"PADD 2023 Y 2024",IF(I36<>"","SOLO 2023",IF(J36<>"","SOLO 2024","NO PARTICIPÓ"))) -> SOLO 2024 | L36: 601571
A37: IQUITOS - 47 | B37: {=DGET(colegios!$A$1:$B965,colegios!$B$1,{colegios!$A$1;L37})} -> 601580 | J37: 1 | K37: =IF(AND(I37<>"",J37<>""),"PADD 2023 Y 2024",IF(I37<>"","SOLO 2023",IF(J37<>"","SOLO 2024","NO PARTICIPÓ"))) -> SOLO 2024 | L37: 601580
A38: IQUITOS - 47 | B38: {=DGET(colegios!$A$1:$B965,colegios!$B$1,{colegios!$A$1;L38})} -> 601678 | J38: 1 | K38: =IF(AND(I38<>"",J38<>""),"PADD 2023 Y 2024",IF(I38<>"","SOLO 2023",IF(J38<>"","SOLO 2024","NO PARTICIPÓ"))) -> SOLO 2024 | L38: 601678
A39: IQUITOS - 47 | B39: {=DGET(colegios!$A$1:$B965,colegios!$B$1,{colegios!$A$1;L39})} -> 6010102 | J39: 1 | K39: =IF(AND(I39<>"",J39<>""),"PADD 2023 Y 2024",IF(I39<>"","SOLO 2023",IF(J39<>"","SOLO 2024","NO PARTICIPÓ"))) -> SOLO 2024 | L39: 6010102
A40: IQUITOS - 47 | B40: {=DGET(colegios!$A$1:$B965,colegios!$B$1,{colegios!$A$1;L40})} -> 6010178 | J40: 1 | K40: =IF(AND(I40<>"",J40<>""),"PADD 2023 Y 2024",IF(I40<>"","SOLO 2023",IF(J40<>"","SOLO 2024","NO PARTICIPÓ"))) -> SOLO 2024 | L40: 6010178
...

Sheet CLASFICACIÓN
F1: AS | G1: A1 | H1: B
F2: CLASIFICACION | G2: ID | H2: PADD
F3: =IF(AND(C3<>"",D3<>"",E3<>""),"LOS 3 AÑOS", IF(AND(C3<>"",IF(AND(C3<>"",D3<>"",E3<>""),"SI","NO")<>"SI",E3<>""),"SOLO 2022 Y 2024",IF(AND(AND(C3="",D3=""),E3<>""),"SOLO 2024",IF(AND(AND(D3<>"",E3<>""),C3=""),"2023 Y 2024", IF(AND(AND(D3="",E3=""),C3<>""),"SOLO LINEA BASE", IF(AND(AND(C3="",E3=""),D3<>""),"SOLO 2023","OTROS ESCENARIOS")))))) -> 2023 Y 2024 | G3: =A3&B3 -> 140452 Primaria | H3: {=IFERROR(DGET('PADD-R'!$B$1:$K953,'PADD-R'!$K$1,{'PADD-R'!$B$1;A3}),"NO PARTICIPÓ")} -> SOLO 2023
F4: =IF(AND(C4<>"",D4<>"",E4<>""),"LOS 3 AÑOS", IF(AND(C4<>"",IF(AND(C4<>"",D4<>"",E4<>""),"SI","NO")<>"SI",E4<>""),"SOLO 2022 Y 2024",IF(AND(AND(C4="",D4=""),E4<>""),"SOLO 2024",IF(AND(AND(D4<>"",E4<>""),C4=""),"2023 Y 2024", IF(AND(AND(D4="",E4=""),C4<>""),"SOLO LINEA BASE", IF(AND(AND(C4="",E4=""),D4<>""),"SOLO 2023","OTROS ESCENARIOS")))))) -> 2023 Y 2024 | G4: =A4&B4 -> 140454 Primaria | H4: {=IFERROR(DGET('PADD-R'!$B$1:$K953,'PADD-R'!$K$1,{'PADD-R'!$B$1;A4}),"NO PARTICIPÓ")} -> SOLO 2023
F5: =IF(AND(C5<>"",D5<>"",E5<>""),"LOS 3 AÑOS", IF(AND(C5<>"",IF(AND(C5<>"",D5<>"",E5<>""),"SI","NO")<>"SI",E5<>""),"SOLO 2022 Y 2024",IF(AND(AND(C5="",D5=""),E5<>""),"SOLO 2024",IF(AND(AND(D5<>"",E5<>""),C5=""),"2023 Y 2024", IF(AND(AND(D5="",E5=""),C5<>""),"SOLO LINEA BASE", IF(AND(AND(C5="",E5=""),D5<>""),"SOLO 2023","OTROS ESCENARIOS")))))) -> 2023 Y 2024 | G5: =A5&B5 -> 140456 Primaria | H5: {=IFERROR(DGET('PADD-R'!$B$1:$K953,'PADD-R'!$K$1,{'PADD-R'!$B$1;A5}),"NO PARTICIPÓ")} -> SOLO 2023
F6: =IF(AND(C6<>"",D6<>"",E6<>""),"LOS 3 AÑOS", IF(AND(C6<>"",IF(AND(C6<>"",D6<>"",E6<>""),"SI","NO")<>"SI",E6<>""),"SOLO 2022 Y 2024",IF(AND(AND(C6="",D6=""),E6<>""),"SOLO 2024",IF(AND(AND(D6<>"",E6<>""),C6=""),"2023 Y 2024", IF(AND(AND(D6="",E6=""),C6<>""),"SOLO LINEA BASE", IF(AND(AND(C6="",E6=""),D6<>""),"SOLO 2023","OTROS ESCENARIOS")))))) -> SOLO 2024 | G6: =A6&B6 -> 141412 Primaria | H6: {=IFERROR(DGET('PADD-R'!$B$1:$K953,'PADD-R'!$K$1,{'PADD-R'!$B$1;A6}),"NO PARTICIPÓ")} -> PADD 2023 Y 2024
F7: =IF(AND(C7<>"",D7<>"",E7<>""),"LOS 3 AÑOS", IF(AND(C7<>"",IF(AND(C7<>"",D7<>"",E7<>""),"SI","NO")<>"SI",E7<>""),"SOLO 2022 Y 2024",IF(AND(AND(C7="",D7=""),E7<>""),"SOLO 2024",IF(AND(AND(D7<>"",E7<>""),C7=""),"2023 Y 2024", IF(AND(AND(D7="",E7=""),C7<>""),"SOLO LINEA BASE", IF(AND(AND(C7="",E7=""),D7<>""),"SOLO 2023","OTROS ESCENARIOS")))))) -> 2023 Y 2024 | G7: =A7&B7 -> 141414 Primaria | H7: {=IFERROR(DGET('PADD-R'!$B$1:$K953,'PADD-R'!$K$1,{'PADD-R'!$B$1;A7}),"NO PARTICIPÓ")} -> PADD 2023 Y 2024
F8: =IF(AND(C8<>"",D8<>"",E8<>""),"LOS 3 AÑOS", IF(AND(C8<>"",IF(AND(C8<>"",D8<>"",E8<>""),"SI","NO")<>"SI",E8<>""),"SOLO 2022 Y 2024",IF(AND(AND(C8="",D8=""),E8<>""),"SOLO 2024",IF(AND(AND(D8<>"",E8<>""),C8=""),"2023 Y 2024", IF(AND(AND(D8="",E8=""),C8<>""),"SOLO LINEA BASE", IF(AND(AND(C8="",E8=""),D8<>""),"SOLO 2023","OTROS ESCENARIOS")))))) -> 2023 Y 2024 | G8: =A8&B8 -> 141416 Primaria | H8: {=IFERROR(DGET('PADD-R'!$B$1:$K953,'PADD-R'!$K$1,{'PADD-R'!$B$1;A8}),"NO PARTICIPÓ")} -> PADD 2023 Y 2024
F9: =IF(AND(C9<>"",D9<>"",E9<>""),"LOS 3 AÑOS", IF(AND(C9<>"",IF(AND(C9<>"",D9<>"",E9<>""),"SI","NO")<>"SI",E9<>""),"SOLO 2022 Y 2024",IF(AND(AND(C9="",D9=""),E9<>""),"SOLO 2024",IF(AND(AND(D9<>"",E9<>""),C9=""),"2023 Y 2024", IF(AND(AND(D9="",E9=""),C9<>""),"SOLO LINEA BASE", IF(AND(AND(C9="",E9=""),D9<>""),"SOLO 2023","OTROS ESCENARIOS")))))) -> SOLO LINEA BASE | G9: =A9&B9 -> 14144 SANTA ROSA1 Primaria | H9: {=IFERROR(DGET('PADD-R'!$B$1:$K953,'PADD-R'!$K$1,{'PADD-R'!$B$1;A9}),"NO PARTICIPÓ")} -> SOLO 2023
F10: =IF(AND(C10<>"",D10<>"",E10<>""),"LOS 3 AÑOS", IF(AND(C10<>"",IF(AND(C10<>"",D10<>"",E10<>""),"SI","NO")<>"SI",E10<>""),"SOLO 2022 Y 2024",IF(AND(AND(C10="",D10=""),E10<>""),"SOLO 2024",IF(AND(AND(D10<>"",E10<>""),C10=""),"2023 Y 2024", IF(AND(AND(D10="",E10=""),C10<>""),"SOLO LINEA BASE", IF(AND(AND(C10="",E10=""),D10<>""),"SOLO 2023","OTROS ESCENARIOS")))))) -> LOS 3 AÑOS | G10: =A10&B10 -> 14144 SANTA ROSA2 Primaria | H10: {=IFERROR(DGET('PADD-R'!$B$1:$K953,'PADD-R'!$K$1,{'PADD-R'!$B$1;A10}),"NO PARTICIPÓ")} -> SOLO 2023
F11: =IF(AND(C11<>"",D11<>"",E11<>""),"LOS 3 AÑOS", IF(AND(C11<>"",IF(AND(C11<>"",D11<>"",E11<>""),"SI","NO")<>"SI",E11<>""),"SOLO 2022 Y 2024",IF(AND(AND(C11="",D11=""),E11<>""),"SOLO 2024",IF(AND(AND(D11<>"",E11<>""),C11=""),"2023 Y 2024", IF(AND(AND(D11="",E11=""),C11<>""),"SOLO LINEA BASE", IF(AND(AND(C11="",E11=""),D11<>""),"SOLO 2023","OTROS ESCENARIOS")))))) -> SOLO LINEA BASE | G11: =A11&B11 -> 14144 SANTA ROSA2 Secundaria | H11: {=IFERROR(DGET('PADD-R'!$B$1:$K953,'PADD-R'!$K$1,{'PADD-R'!$B$1;A11}),"NO PARTICIPÓ")} -> SOLO 2023
F12: =IF(AND(C12<>"",D12<>"",E12<>""),"LOS 3 AÑOS", IF(AND(C12<>"",IF(AND(C12<>"",D12<>"",E12<>""),"SI","NO")<>"SI",E12<>""),"SOLO 2022 Y 2024",IF(AND(AND(C12="",D12=""),E12<>""),"SOLO 2024",IF(AND(AND(D12<>"",E12<>""),C12=""),"2023 Y 2024", IF(AND(AND(D12="",E12=""),C12<>""),"SOLO LINEA BASE", IF(AND(AND(C12="",E12=""),D12<>""),"SOLO 2023","OTROS ESCENARIOS")))))) -> LOS 3 AÑOS | G12: =A12&B12 -> 14144 SANTA ROSA4 Primaria | H12: {=IFERROR(DGET('PADD-R'!$B$1:$K953,'PADD-R'!$K$1,{'PADD-R'!$B$1;A12}),"NO PARTICIPÓ")} -> SOLO 2023
F13: =IF(AND(C13<>"",D13<>"",E13<>""),"LOS 3 AÑOS", IF(AND(C13<>"",IF(AND(C13<>"",D13<>"",E13<>""),"SI","NO")<>"SI",E13<>""),"SOLO 2022 Y 2024",IF(AND(AND(C13="",D13=""),E13<>""),"SOLO 2024",IF(AND(AND(D13<>"",E13<>""),C13=""),"2023 Y 2024", IF(AND(AND(D13="",E13=""),C13<>""),"SOLO LINEA BASE", IF(AND(AND(C13="",E13=""),D13<>""),"SOLO 2023","OTROS ESCENARIOS")))))) -> SOLO LINEA BASE | G13: =A13&B13 -> 14144 SANTA ROSA4 Secundaria | H13: {=IFERROR(DGET('PADD-R'!$B$1:$K953,'PADD-R'!$K$1,{'PADD-R'!$B$1;A13}),"NO PARTICIPÓ")} -> SOLO 2023
F14: =IF(AND(C14<>"",D14<>"",E14<>""),"LOS 3 AÑOS", IF(AND(C14<>"",IF(AND(C14<>"",D14<>"",E14<>""),"SI","NO")<>"SI",E14<>""),"SOLO 2022 Y 2024",IF(AND(AND(C14="",D14=""),E14<>""),"SOLO 2024",IF(AND(AND(D14<>"",E14<>""),C14=""),"2023 Y 2024", IF(AND(AND(D14="",E14=""),C14<>""),"SOLO LINEA BASE", IF(AND(AND(C14="",E14=""),D14<>""),"SOLO 2023","OTROS ESCENARIOS")))))) -> LOS 3 AÑOS | G14: =A14&B14 -> 14144 SANTA ROSA6 Primaria | H14: {=IFERROR(DGET('PADD-R'!$B$1:$K953,'PADD-R'!$K$1,{'PADD-R'!$B$1;A14}),"NO PARTICIPÓ")} -> SOLO 2023
F15: =IF(AND(C15<>"",D15<>"",E15<>""),"LOS 3 AÑOS", IF(AND(C15<>"",IF(AND(C15<>"",D15<>"",E15<>""),"SI","NO")<>"SI",E15<>""),"SOLO 2022 Y 2024",IF(AND(AND(C15="",D15=""),E15<>""),"SOLO 2024",IF(AND(AND(D15<>"",E15<>""),C15=""),"2023 Y 2024", IF(AND(AND(D15="",E15=""),C15<>""),"SOLO LINEA BASE", IF(AND(AND(C15="",E15=""),D15<>""),"SOLO 2023","OTROS ESCENARIOS")))))) -> SOLO LINEA BASE | G15: =A15&B15 -> 14145 SANTA JULIA BILLIART1 Primaria | H15: {=IFERROR(DGET('PADD-R'!$B$1:$K953,'PADD-R'!$K$1,{'PADD-R'!$B$1;A15}),"NO PARTICIPÓ")} -> SOLO 2023
F16: =IF(AND(C16<>"",D16<>"",E16<>""),"LOS 3 AÑOS", IF(AND(C16<>"",IF(AND(C16<>"",D16<>"",E16<>""),"SI","NO")<>"SI",E16<>""),"SOLO 2022 Y 2024",IF(AND(AND(C16="",D16=""),E16<>""),"SOLO 2024",IF(AND(AND(D16<>"",E16<>""),C16=""),"2023 Y 2024", IF(AND(AND(D16="",E16=""),C16<>""),"SOLO LINEA BASE", IF(AND(AND(C16="",E16=""),D16<>""),"SOLO 2023","OTROS ESCENARIOS")))))) -> LOS 3 AÑOS | G16: =A16&B16 -> 14145 SANTA JULIA BILLIART2 Primaria | H16: {=IFERROR(DGET('PADD-R'!$B$1:$K953,'PADD-R'!$K$1,{'PADD-R'!$B$1;A16}),"NO PARTICIPÓ")} -> SOLO 2023
F17: =IF(AND(C17<>"",D17<>"",E17<>""),"LOS 3 AÑOS", IF(AND(C17<>"",IF(AND(C17<>"",D17<>"",E17<>""),"SI","NO")<>"SI",E17<>""),"SOLO 2022 Y 2024",IF(AND(AND(C17="",D17=""),E17<>""),"SOLO 2024",IF(AND(AND(D17<>"",E17<>""),C17=""),"2023 Y 2024", IF(AND(AND(D17="",E17=""),C17<>""),"SOLO LINEA BASE", IF(AND(AND(C17="",E17=""),D17<>""),"SOLO 2023","OTROS ESCENARIOS")))))) -> LOS 3 AÑOS | G17: =A17&B17 -> 14145 SANTA JULIA BILLIART4 Primaria | H17: {=IFERROR(DGET('PADD-R'!$B$1:$K953,'PADD-R'!$K$1,{'PADD-R'!$B$1;A17}),"NO PARTICIPÓ")} -> SOLO 2023
F18: =IF(AND(C18<>"",D18<>"",E18<>""),"LOS 3 AÑOS", IF(AND(C18<>"",IF(AND(C18<>"",D18<>"",E18<>""),"SI","NO")<>"SI",E18<>""),"SOLO 2022 Y 2024",IF(AND(AND(C18="",D18=""),E18<>""),"SOLO 2024",IF(AND(AND(D18<>"",E18<>""),C18=""),"2023 Y 2024", IF(AND(AND(D18="",E18=""),C18<>""),"SOLO LINEA BASE", IF(AND(AND(C18="",E18=""),D18<>""),"SOLO 2023","OTROS ESCENARIOS")))))) -> LOS 3 AÑOS | G18: =A18&B18 -> 14145 SANTA JULIA BILLIART6 Primaria | H18: {=IFERROR(DGET('PADD-R'!$B$1:$K953,'PADD-R'!$K$1,{'PADD-R'!$B$1;A18}),"NO PARTICIPÓ")} -> SOLO 2023
F19: =IF(AND(C19<>"",D19<>"",E19<>""),"LOS 3 AÑOS", IF(AND(C19<>"",IF(AND(C19<>"",D19<>"",E19<>""),"SI","NO")<>"SI",E19<>""),"SOLO 2022 Y 2024",IF(AND(AND(C19="",D19=""),E19<>""),"SOLO 2024",IF(AND(AND(D19<>"",E19<>""),C19=""),"2023 Y 2024", IF(AND(AND(D19="",E19=""),C19<>""),"SOLO LINEA BASE", IF(AND(AND(C19="",E19=""),D19<>""),"SOLO 2023","OTROS ESCENARIOS")))))) -> SOLO LINEA BASE | G19: =A19&B19 -> 1457365 LOS RIT'S DEL ALTO ANDINO2 Secundaria | H19: {=IFERROR(DGET('PADD-R'!$B$1:$K953,'PADD-R'!$K$1,{'PADD-R'!$B$1;A19}),"NO PARTICIPÓ")} -> NO PARTICIPÓ
F20: =IF(AND(C20<>"",D20<>"",E20<>""),"LOS 3 AÑOS", IF(AND(C20<>"",IF(AND(C20<>"",D20<>"",E20<>""),"SI","NO")<>"SI",E20<>""),"SOLO 2022 Y 2024",IF(AND(AND(C20="",D20=""),E20<>""),"SOLO 2024",IF(AND(AND(D20<>"",E20<>""),C20=""),"2023 Y 2024", IF(AND(AND(D20="",E20=""),C20<>""),"SOLO LINEA BASE", IF(AND(AND(C20="",E20=""),D20<>""),"SOLO 2023","OTROS ESCENARIOS")))))) -> SOLO LINEA BASE | G20: =A20&B20 -> 1457365 LOS RIT'S DEL ALTO ANDINO5 Secundaria | H20: {=IFERROR(DGET('PADD-R'!$B$1:$K953,'PADD-R'!$K$1,{'PADD-R'!$B$1;A20}),"NO PARTICIPÓ")} -> NO PARTICIPÓ
F21: =IF(AND(C21<>"",D21<>"",E21<>""),"LOS 3 AÑOS", IF(AND(C21<>"",IF(AND(C21<>"",D21<>"",E21<>""),"SI","NO")<>"SI",E21<>""),"SOLO 2022 Y 2024",IF(AND(AND(C21="",D21=""),E21<>""),"SOLO 2024",IF(AND(AND(D21<>"",E21<>""),C21=""),"2023 Y 2024", IF(AND(AND(D21="",E21=""),C21<>""),"SOLO LINEA BASE", IF(AND(AND(C21="",E21=""),D21<>""),"SOLO 2023","OTROS ESCENARIOS")))))) -> SOLO LINEA BASE | G21: =A21&B21 -> 148941 Primaria | H21: {=IFERROR(DGET('PADD-R'!$B$1:$K953,'PADD-R'!$K$1,{'PADD-R'!$B$1;A21}),"NO PARTICIPÓ")} -> SOLO 2024
F22: =IF(AND(C22<>"",D22<>"",E22<>""),"LOS 3 AÑOS", IF(AND(C22<>"",IF(AND(C22<>"",D22<>"",E22<>""),"SI","NO")<>"SI",E22<>""),"SOLO 2022 Y 2024",IF(AND(AND(C22="",D22=""),E22<>""),"SOLO 2024",IF(AND(AND(D22<>"",E22<>""),C22=""),"2023 Y 2024", IF(AND(AND(D22="",E22=""),C22<>""),"SOLO LINEA BASE", IF(AND(AND(C22="",E22=""),D22<>""),"SOLO 2023","OTROS ESCENARIOS")))))) -> SOLO 2022 Y 2024 | G22: =A22&B22 -> 148942 Primaria | H22: {=IFERROR(DGET('PADD-R'!$B$1:$K953,'PADD-R'!$K$1,{'PADD-R'!$B$1;A22}),"NO PARTICIPÓ")} -> SOLO 2024
F23: =IF(AND(C23<>"",D23<>"",E23<>""),"LOS 3 AÑOS", IF(AND(C23<>"",IF(AND(C23<>"",D23<>"",E23<>""),"SI","NO")<>"SI",E23<>""),"SOLO 2022 Y 2024",IF(AND(AND(C23="",D23=""),E23<>""),"SOLO 2024",IF(AND(AND(D23<>"",E23<>""),C23=""),"2023 Y 2024", IF(AND(AND(D23="",E23=""),C23<>""),"SOLO LINEA BASE", IF(AND(AND(C23="",E23=""),D23<>""),"SOLO 2023","OTROS ESCENARIOS")))))) -> SOLO 2022 Y 2024 | G23: =A23&B23 -> 148944 Primaria | H23: {=IFERROR(DGET('PADD-R'!$B$1:$K953,'PADD-R'!$K$1,{'PADD-R'!$B$1;A23}),"NO PARTICIPÓ")} -> SOLO 2024
F24: =IF(AND(C24<>"",D24<>"",E24<>""),"LOS 3 AÑOS", IF(AND(C24<>"",IF(AND(C24<>"",D24<>"",E24<>""),"SI","NO")<>"SI",E24<>""),"SOLO 2022 Y 2024",IF(AND(AND(C24="",D24=""),E24<>""),"SOLO 2024",IF(AND(AND(D24<>"",E24<>""),C24=""),"2023 Y 2024", IF(AND(AND(D24="",E24=""),C24<>""),"SOLO LINEA BASE", IF(AND(AND(C24="",E24=""),D24<>""),"SOLO 2023","OTROS ESCENARIOS")))))) -> SOLO LINEA BASE | G24: =A24&B24 -> 148946 Primaria | H24: {=IFERROR(DGET('PADD-R'!$B$1:$K953,'PADD-R'!$K$1,{'PADD-R'!$B$1;A24}),"NO PARTICIPÓ")} -> SOLO 2024
F25: =IF(AND(C25<>"",D25<>"",E25<>""),"LOS 3 AÑOS", IF(AND(C25<>"",IF(AND(C25<>"",D25<>"",E25<>""),"SI","NO")<>"SI",E25<>""),"SOLO 2022 Y 2024",IF(AND(AND(C25="",D25=""),E25<>""),"SOLO 2024",IF(AND(AND(D25<>"",E25<>""),C25=""),"2023 Y 2024", IF(AND(AND(D25="",E25=""),C25<>""),"SOLO LINEA BASE", IF(AND(AND(C25="",E25=""),D25<>""),"SOLO 2023","OTROS ESCENARIOS")))))) -> 2023 Y 2024 | G25: =A25&B25 -> 14924 DANIEL ALCIDES CARRION2 Primaria | H25: {=IFERROR(DGET('PADD-R'!$B$1:$K953,'PADD-R'!$K$1,{'PADD-R'!$B$1;A25}),"NO PARTICIPÓ")} -> PADD 2023 Y 2024
F26: =IF(AND(C26<>"",D26<>"",E26<>""),"LOS 3 AÑOS", IF(AND(C26<>"",IF(AND(C26<>"",D26<>"",E26<>""),"SI","NO")<>"SI",E26<>""),"SOLO 2022 Y 2024",IF(AND(AND(C26="",D26=""),E26<>""),"SOLO 2024",IF(AND(AND(D26<>"",E26<>""),C26=""),"2023 Y 2024", IF(AND(AND(D26="",E26=""),C26<>""),"SOLO LINEA BASE", IF(AND(AND(C26="",E26=""),D26<>""),"SOLO 2023","OTROS ESCENARIOS")))))) -> SOLO 2024 | G26: =A26&B26 -> 14924 DANIEL ALCIDES CARRION4 Primaria | H26: {=IFERROR(DGET('PADD-R'!$B$1:$K953,'PADD-R'!$K$1,{'PADD-R'!$B$1;A26}),"NO PARTICIPÓ")} -> PADD 2023 Y 2024
F27: =IF(AND(C27<>"",D27<>"",E27<>""),"LOS 3 AÑOS", IF(AND(C27<>"",IF(AND(C27<>"",D27<>"",E27<>""),"SI","NO")<>"SI",E27<>""),"SOLO 2022 Y 2024",IF(AND(AND(C27="",D27=""),E27<>""),"SOLO 2024",IF(AND(AND(D27<>"",E27<>""),C27=""),"2023 Y 2024", IF(AND(AND(D27="",E27=""),C27<>""),"SOLO LINEA BASE", IF(AND(AND(C27="",E27=""),D27<>""),"SOLO 2023","OTROS ESCENARIOS")))))) -> SOLO 2024 | G27: =A27&B27 -> 14924 DANIEL ALCIDES CARRION6 Primaria | H27: {=IFERROR(DGET('PADD-R'!$B$1:$K953,'PADD-R'!$K$1,{'PADD-R'!$B$1;A27}),"NO PARTICIPÓ")} -> PADD 2023 Y 2024
F28: =IF(AND(C28<>"",D28<>"",E28<>""),"LOS 3 AÑOS", IF(AND(C28<>"",IF(AND(C28<>"",D28<>"",E28<>""),"SI","NO")<>"SI",E28<>""),"SOLO 2022 Y 2024",IF(AND(AND(C28="",D28=""),E28<>""),"SOLO 2024",IF(AND(AND(D28<>"",E28<>""),C28=""),"2023 Y 2024", IF(AND(AND(D28="",E28=""),C28<>""),"SOLO LINEA BASE", IF(AND(AND(C28="",E28=""),D28<>""),"SOLO 2023","OTROS ESCENARIOS")))))) -> 2023 Y 2024 | G28: =A28&B28 -> 149752 Primaria | H28: {=IFERROR(DGET('PADD-R'!$B$1:$K953,'PADD-R'!$K$1,{'PADD-R'!$B$1;A28}),"NO PARTICIPÓ")} -> PADD 2023 Y 2024
F29: =IF(AND(C29<>"",D29<>"",E29<>""),"LOS 3 AÑOS", IF(AND(C29<>"",IF(AND(C29<>"",D29<>"",E29<>""),"SI","NO")<>"SI",E29<>""),"SOLO 2022 Y 2024",IF(AND(AND(C29="",D29=""),E29<>""),"SOLO 2024",IF(AND(AND(D29<>"",E29<>""),C29=""),"2023 Y 2024", IF(AND(AND(D29="",E29=""),C29<>""),"SOLO LINEA BASE", IF(AND(AND(C29="",E29=""),D29<>""),"SOLO 2023","OTROS ESCENARIOS")))))) -> SOLO 2024 | G29: =A29&B29 -> 149754 Primaria | H29: {=IFERROR(DGET('PADD-R'!$B$1:$K953,'PADD-R'!$K$1,{'PADD-R'!$B$1;A29}),"NO PARTICIPÓ")} -> PADD 2023 Y 2024
F30: =IF(AND(C30<>"",D30<>"",E30<>""),"LOS 3 AÑOS", IF(AND(C30<>"",IF(AND(C30<>"",D30<>"",E30<>""),"SI","NO")<>"SI",E30<>""),"SOLO 2022 Y 2024",IF(AND(AND(C30="",D30=""),E30<>""),"SOLO 2024",IF(AND(AND(D30<>"",E30<>""),C30=""),"2023 Y 2024", IF(AND(AND(D30="",E30=""),C30<>""),"SOLO LINEA BASE", IF(AND(AND(C30="",E30=""),D30<>""),"SOLO 2023","OTROS ESCENARIOS")))))) -> 2023 Y 2024 | G30: =A30&B30 -> 149756 Primaria | H30: {=IFERROR(DGET('PADD-R'!$B$1:$K953,'PADD-R'!$K$1,{'PADD-R'!$B$1;A30}),"NO PARTICIPÓ")} -> PADD 2023 Y 2024
F31: =IF(AND(C31<>"",D31<>"",E31<>""),"LOS 3 AÑOS", IF(AND(C31<>"",IF(AND(C31<>"",D31<>"",E31<>""),"SI","NO")<>"SI",E31<>""),"SOLO 2022 Y 2024",IF(AND(AND(C31="",D31=""),E31<>""),"SOLO 2024",IF(AND(AND(D31<>"",E31<>""),C31=""),"2023 Y 2024", IF(AND(AND(D31="",E31=""),C31<>""),"SOLO LINEA BASE", IF(AND(AND(C31="",E31=""),D31<>""),"SOLO 2023","OTROS ESCENARIOS")))))) -> 2023 Y 2024 | G31: =A31&B31 -> 152192 Primaria | H31: {=IFERROR(DGET('PADD-R'!$B$1:$K953,'PADD-R'!$K$1,{'PADD-R'!$B$1;A31}),"NO PARTICIPÓ")} -> SOLO 2023
F32: =IF(AND(C32<>"",D32<>"",E32<>""),"LOS 3 AÑOS", IF(AND(C32<>"",IF(AND(C32<>"",D32<>"",E32<>""),"SI","NO")<>"SI",E32<>""),"SOLO 2022 Y 2024",IF(AND(AND(C32="",D32=""),E32<>""),"SOLO 2024",IF(AND(AND(D32<>"",E32<>""),C32=""),"2023 Y 2024", IF(AND(AND(D32="",E32=""),C32<>""),"SOLO LINEA BASE", IF(AND(AND(C32="",E32=""),D32<>""),"SOLO 2023","OTROS ESCENARIOS")))))) -> SOLO 2023 | G32: =A32&B32 -> 152194 Primaria | H32: {=IFERROR(DGET('PADD-R'!$B$1:$K953,'PADD-R'!$K$1,{'PADD-R'!$B$1;A32}),"NO PARTICIPÓ")} -> SOLO 2023
F33: =IF(AND(C33<>"",D33<>"",E33<>""),"LOS 3 AÑOS", IF(AND(C33<>"",IF(AND(C33<>"",D33<>"",E33<>""),"SI","NO")<>"SI",E33<>""),"SOLO 2022 Y 2024",IF(AND(AND(C33="",D33=""),E33<>""),"SOLO 2024",IF(AND(AND(D33<>"",E33<>""),C33=""),"2023 Y 2024", IF(AND(AND(D33="",E33=""),C33<>""),"SOLO LINEA BASE", IF(AND(AND(C33="",E33=""),D33<>""),"SOLO 2023","OTROS ESCENARIOS")))))) -> 2023 Y 2024 | G33: =A33&B33 -> 152196 Primaria | H33: {=IFERROR(DGET('PADD-R'!$B$1:$K953,'PADD-R'!$K$1,{'PADD-R'!$B$1;A33}),"NO PARTICIPÓ")} -> SOLO 2023
F34: =IF(AND(C34<>"",D34<>"",E34<>""),"LOS 3 AÑOS", IF(AND(C34<>"",IF(AND(C34<>"",D34<>"",E34<>""),"SI","NO")<>"SI",E34<>""),"SOLO 2022 Y 2024",IF(AND(AND(C34="",D34=""),E34<>""),"SOLO 2024",IF(AND(AND(D34<>"",E34<>""),C34=""),"2023 Y 2024", IF(AND(AND(D34="",E34=""),C34<>""),"SOLO LINEA BASE", IF(AND(AND(C34="",E34=""),D34<>""),"SOLO 2023","OTROS ESCENARIOS")))))) -> SOLO 2023 | G34: =A34&B34 -> 152202 Primaria | H34: {=IFERROR(DGET('PADD-R'!$B$1:$K953,'PADD-R'!$K$1,{'PADD-R'!$B$1;A34}),"NO PARTICIPÓ")} -> SOLO 2023
F35: =IF(AND(C35<>"",D35<>"",E35<>""),"LOS 3 AÑOS", IF(AND(C35<>"",IF(AND(C35<>"",D35<>"",E35<>""),"SI","NO")<>"SI",E35<>""),"SOLO 2022 Y 2024",IF(AND(AND(C35="",D35=""),E35<>""),"SOLO 2024",IF(AND(AND(D35<>"",E35<>""),C35=""),"2023 Y 2024", IF(AND(AND(D35="",E35=""),C35<>""),"SOLO LINEA BASE", IF(AND(AND(C35="",E35=""),D35<>""),"SOLO 2023","OTROS ESCENARIOS")))))) -> SOLO 2023 | G35: =A35&B35 -> 152204 Primaria | H35: {=IFERROR(DGET('PADD-R'!$B$1:$K953,'PADD-R'!$K$1,{'PADD-R'!$B$1;A35}),"NO PARTICIPÓ")} -> SOLO 2023
F36: =IF(AND(C36<>"",D36<>"",E36<>""),"LOS 3 AÑOS", IF(AND(C36<>"",IF(AND(C36<>"",D36<>"",E36<>""),"SI","NO")<>"SI",E36<>""),"SOLO 2022 Y 2024",IF(AND(AND(C36="",D36=""),E36<>""),"SOLO 2024",IF(AND(AND(D36<>"",E36<>""),C36=""),"2023 Y 2024", IF(AND(AND(D36="",E36=""),C36<>""),"SOLO LINEA BASE", IF(AND(AND(C36="",E36=""),D36<>""),"SOLO 2023","OTROS ESCENARIOS")))))) -> 2023 Y 2024 | G36: =A36&B36 -> 152206 Primaria | H36: {=IFERROR(DGET('PADD-R'!$B$1:$K953,'PADD-R'!$K$1,{'PADD-R'!$B$1;A36}),"NO PARTICIPÓ")} -> SOLO 2023
F37: =IF(AND(C37<>"",D37<>"",E37<>""),"LOS 3 AÑOS", IF(AND(C37<>"",IF(AND(C37<>"",D37<>"",E37<>""),"SI","NO")<>"SI",E37<>""),"SOLO 2022 Y 2024",IF(AND(AND(C37="",D37=""),E37<>""),"SOLO 2024",IF(AND(AND(D37<>"",E37<>""),C37=""),"2023 Y 2024", IF(AND(AND(D37="",E37=""),C37<>""),"SOLO LINEA BASE", IF(AND(AND(C37="",E37=""),D37<>""),"SOLO 2023","OTROS ESCENARIOS")))))) -> 2023 Y 2024 | G37: =A37&B37 -> 153042 Primaria | H37: {=IFERROR(DGET('PADD-R'!$B$1:$K953,'PADD-R'!$K$1,{'PADD-R'!$B$1;A37}),"NO PARTICIPÓ")} -> SOLO 2023
F38: =IF(AND(C38<>"",D38<>"",E38<>""),"LOS 3 AÑOS", IF(AND(C38<>"",IF(AND(C38<>"",D38<>"",E38<>""),"SI","NO")<>"SI",E38<>""),"SOLO 2022 Y 2024",IF(AND(AND(C38="",D38=""),E38<>""),"SOLO 2024",IF(AND(AND(D38<>"",E38<>""),C38=""),"2023 Y 2024", IF(AND(AND(D38="",E38=""),C38<>""),"SOLO LINEA BASE", IF(AND(AND(C38="",E38=""),D38<>""),"SOLO 2023","OTROS ESCENARIOS")))))) -> 2023 Y 2024 | G38: =A38&B38 -> 153044 Primaria | H38: {=IFERROR(DGET('PADD-R'!$B$1:$K953,'PADD-R'!$K$1,{'PADD-R'!$B$1;A38}),"NO PARTICIPÓ")} -> SOLO 2023
F39: =IF(AND(C39<>"",D39<>"",E39<>""),"LOS 3 AÑOS", IF(AND(C39<>"",IF(AND(C39<>"",D39<>"",E39<>""),"SI","NO")<>"SI",E39<>""),"SOLO 2022 Y 2024",IF(AND(AND(C39="",D39=""),E39<>""),"SOLO 2024",IF(AND(AND(D39<>"",E39<>""),C39=""),"2023 Y 2024", IF(AND(AND(D39="",E39=""),C39<>""),"SOLO LINEA BASE", IF(AND(AND(C39="",E39=""),D39<>""),"SOLO 2023","OTROS ESCENARIOS")))))) -> 2023 Y 2024 | G39: =A39&B39 -> 153046 Primaria | H39: {=IFERROR(DGET('PADD-R'!$B$1:$K953,'PADD-R'!$K$1,{'PADD-R'!$B$1;A39}),"NO PARTICIPÓ")} -> SOLO 2023
F40: =IF(AND(C40<>"",D40<>"",E40<>""),"LOS 3 AÑOS", IF(AND(C40<>"",IF(AND(C40<>"",D40<>"",E40<>""),"SI","NO")<>"SI",E40<>""),"SOLO 2022 Y 2024",IF(AND(AND(C40="",D40=""),E40<>""),"SOLO 2024",IF(AND(AND(D40<>"",E40<>""),C40=""),"2023 Y 2024", IF(AND(AND(D40="",E40=""),C40<>""),"SOLO LINEA BASE", IF(AND(AND(C40="",E40=""),D40<>""),"SOLO 2023","OTROS ESCENARIOS")))))) -> SOLO 2023 | G40: =A40&B40 -> 153832 Primaria | H40: {=IFERROR(DGET('PADD-R'!$B$1:$K953,'PADD-R'!$K$1,{'PADD-R'!$B$1;A40}),"NO PARTICIPÓ")} -> PADD 2023 Y 2024
...

Sheet GLOBAL
A2: RESULTADO GENERAL 5 RER
N4: 55 | O4: 45 | P4: 1 | Q4: 39 | R4: 59 | S4: 2
N5: 59 | O5: 38 | P5: 3 | Q5: 44 | R5: 55 | S5: 1
N6: 76 | O6: 23 | P6: 1 | Q6: 70 | R6: 30 | S6: 0
N7: 44 | O7: 55 | P7: 1 | Q7: 59 | R7: 40 | S7: 1
N8: 52 | O8: 47 | P8: 2 | Q8: 97 | R8: 3 | S8: 0
B15: Grado | C15: =C4 -> 2022 | F15: =E4 -> 2023 | I15: =H4 -> 2024
C16: Inicio | D16: Proceso | E16: Satisfactorio | F16: Inicio | G16: Proceso | H16: Satisfactorio | I16: Inicio | J16: Proceso | K16: Satisfactorio
B17: 2 Primaria | C17: =N4/100 -> 0.55 | D17: =O4/100 -> 0.45 | E17: =P4/100 -> 0.01 | F17: =Q4/100 -> 0.39 | G17: =R4/100 -> 0.59 | H17: =S4/100 -> 0.02 | I17: =ROUND(H6/SUM($H6:$J6),3) -> 0.318 | J17: =ROUND(I6/SUM($H6:$J6),3) -> 0.657 | K17: =ROUND(J6/SUM($H6:$J6),3) -> 0.026
B18: 4 Primaria | C18: =N5/100 -> 0.59 | D18: =O5/100 -> 0.38 | E18: =P5/100 -> 0.03 | F18: =Q5/100 -> 0.44 | G18: =R5/100 -> 0.55 | H18: =S5/100 -> 0.01 | I18: =ROUND(H7/SUM($H7:$J7),3) -> 0.315 | J18: =ROUND(I7/SUM($H7:$J7),3) -> 0.667 | K18: =ROUND(J7/SUM($H7:$J7),3) -> 0.019
B19: 6 Primaria | C19: =N6/100 -> 0.76 | D19: =O6/100 -> 0.23 | E19: =P6/100 -> 0.01 | F19: =Q6/100 -> 0.7 | G19: =R6/100 -> 0.3 | H19: =S6/100 -> 0 | I19: =ROUND(H8/SUM($H8:$J8),3) -> 0.531 | J19: =ROUND(I8/SUM($H8:$J8),3) -> 0.456 | K19: =ROUND(J8/SUM($H8:$J8),3) -> 0.013
B20: 2 Secundaria | C20: =N7/100 -> 0.44 | D20: =O7/100 -> 0.55 | E20: =P7/100 -> 0.01 | F20: =Q7/100 -> 0.59 | G20: =R7/100 -> 0.4 | H20: =S7/100 -> 0.01 | I20: =ROUND(H9/SUM($H9:$J9),3) -> 0.793 | J20: =ROUND(I9/SUM($H9:$J9),3) -> 0.207 | K20: =ROUND(J9/SUM($H9:$J9),3) -> 0
B21: 4 Secundaria | C21: =N8/100 -> 0.52 | D21: =O8/100 -> 0.47 | E21: =P8/100 -> 0.02 | F21: =Q8/100 -> 0.97 | G21: =R8/100 -> 0.03 | H21: =S8/100 -> 0 | I21: =ROUND(H10/SUM($H10:$J10),3) -> 0.83 | J21: =ROUND(I10/SUM($H10:$J10),3) -> 0.17 | K21: =ROUND(J10/SUM($H10:$J10),3) -> 0
A25: RESULTADO GENERAL RER CUSCO
N27: 0.81 | O27: 0.19 | P27: 0 | Q27: 0.56 | R27: 0.42 | S27: 0.02 | T27: 0.28813559 | U27: 0.50847458 | V27: 0.20338983
N28: 0.91 | O28: 0.09 | P28: 0 | Q28: 0.67 | R28: 0.26 | S28: 0.07 | T28: 0.51351351 | U28: 0.36486486 | V28: 0.12162162
N29: 0.83 | O29: 0.17 | P29: 0 | Q29: 0.5 | R29: 0.46 | S29: 0.04 | T29: 0.24285714 | U29: 0.5 | V29: 0.25714286
B38: Grado | C38: =C27 -> 2022 | F38: =F27 -> 2023 | I38: =I27 -> 2024
C39: Inicio | D39: Proceso | E39: Satisfactorio | F39: Inicio | G39: Proceso | H39: Satisfactorio | I39: Inicio | J39: Proceso | K39: Satisfactorio
B40: 2 Primaria | C40: 0.81 | D40: 0.19 | E40: 0 | F40: 0.56 | G40: 0.42 | H40: 0.02 | I40: =I29/SUM($I29:$K29) -> 0.28813559 | J40: =J29/SUM($I29:$K29) -> 0.50847458 | K40: =K29/SUM($I29:$K29) -> 0.20338983
B41: 4 Primaria | C41: 0.91 | D41: 0.09 | E41: 0 | F41: 0.67 | G41: 0.26 | H41: 0.07 | I41: =I30/SUM($I30:$K30) -> 0.51351351 | J41: =J30/SUM($I30:$K30) -> 0.36486486 | K41: =K30/SUM($I30:$K30) -> 0.12162162
B42: 6 Primaria | C42: 0.83 | D42: 0.17 | E42: 0 | F42: 0.5 | G42: 0.46 | H42: 0.04 | I42: =I31/SUM($I31:$K31) -> 0.24285714 | J42: =J31/SUM($I31:$K31) -> 0.5 | K42: =K31/SUM($I31:$K31) -> 0.25714286
B43: 2 Secundaria | I43: =I32/SUM($I32:$K32) -> 1 | J43: =J32/SUM($I32:$K32) -> 0 | K43: =K32/SUM($I32:$K32) -> 0
B44: 4 Secundaria | I44: =I33/SUM($I33:$K33) -> 1 | J44: =J33/SUM($I33:$K33) -> 0 | K44: =K33/SUM($I33:$K33) -> 0

Sheet LOS 3 AÑOS
O2: IE | P2: GRADO | Q2: =E2 -> 2022 | T2: =H2 -> 2023 | W2: =K2 -> 2024
Q3: Inicio | R3: Proceso | S3: Satisfactorio | T3: Inicio | U3: Proceso | V3: Satisfactorio | W3: Inicio | X3: Proceso | Y3: Satisfactorio
O4: =B4 -> 501432 PAPA FRANCISCO I | P4: =D4 -> 2 Primaria | Q4: =E4/SUM($E4:$G4) -> 1 | R4: =F4/SUM($E4:$G4) -> 0 | S4: =G4/SUM($E4:$G4) -> 0 | T4: =H4/SUM($H4:$J4) -> 1 | U4: =I4/SUM($H4:$J4) -> 0 | V4: =J4/SUM($H4:$J4) -> 0 | W4: =K4/SUM($K4:$M4) -> 0.33333333 | X4: =L4/SUM($K4:$M4) -> 0.66666667 | Y4: =M4/SUM($K4:$M4) -> 0
